Workbook

Sheet Input
A1: Tiempo | B1: Evento
A2: 1 | B2: E58
A3: 2 | B3: E97
A4: 3 | B4: E48
A5: 4 | B5: E8
A6: 5 | B6: E48
A7: 6 | B7: E63
A8: 7 | B8: E62
A9: 8 | B9: E65
A10: 9 | B10: E62
A11: 10 | B11: E97
A12: 11 | B12: E48
A13: 12 | B13: E62
... A230: 229 | B230: E81

Sheet DatosV
B1: Episodios
A2: Qué ocurre | B2: Código | C2: Episodio 1 | D2: Episodio 2 | E2: Episodio 3 | F2: Episodio 4 | G2: Episodio 5 | H2: Episodio 6 | I2: Episodio 7 | J2: Episodio 8 | K2: Episodio 9 | L2: Episodio 10
A3: Greg y Wirt Vagan | B3: =VLOOKUP(A3, 'Asignar letras'!$A$2:$B$100, 2, 0) -> E58 | C3: =IFERROR(IF( VLOOKUP(B3, Todo!$A$4:$B$28, 2, FALSE) = C$2, "X", ""), "") -> X | D3: =IFERROR(IF( VLOOKUP($B3, Todo!$A$29:$B$46, 2, FALSE) = D$2, "X", ""), "") | E3: =IFERROR(IF( VLOOKUP($B3, Todo!$A$47:$B$67, 2, FALSE) = E$2, "X", ""), "") | F3: =IFERROR(IF( VLOOKUP($B3, Todo!$A$68:$B$86, 2, FALSE) = F$2, "X", ""), "") | G3: =IFERROR(IF( VLOOKUP($B3, Todo!$A$87:$B$102, 2, FALSE) = G$2, "X", ""), "") | H3: =IFERROR(IF( VLOOKUP($B3, Todo!$A$103:$B$120, 2, FALSE) = H$2, "X", ""), "") | I3: =IFERROR(IF( VLOOKUP($B3,Todo!$A$121:$B$130, 2, FALSE) = I$2, "X", ""), "") | J3: =IFERROR(IF( VLOOKUP($B3,Todo!$A$131:$B$152, 2, FALSE) = J$2, "X", ""), "") | K3: =IFERROR(IF( VLOOKUP($B3,Todo!$A$153:$B$170, 2, FALSE) = K$2, "X", ""), "") | L3: =IFERROR(IF( VLOOKUP($B3,Todo!$A$172:$B$238, 2, FALSE) = L$2, "X", ""), "")
A4: Wirt se preocupa | B4: =VLOOKUP(A4, 'Asignar letras'!$A$2:$B$100, 2, 0) -> E97 | C4: =IFERROR(IF( VLOOKUP(B4, Todo!$A$4:$B$28, 2, FALSE) = C$2, "X", ""), "") -> X | D4: =IFERROR(IF( VLOOKUP($B4, Todo!$A$29:$B$46, 2, FALSE) = D$2, "X", ""), "") | E4: =IFERROR(IF( VLOOKUP($B4, Todo!$A$47:$B$67, 2, FALSE) = E$2, "X", ""), "") | F4: =IFERROR(IF( VLOOKUP($B4, Todo!$A$68:$B$86, 2, FALSE) = F$2, "X", ""), "") -> X | G4: =IFERROR(IF( VLOOKUP($B4, Todo!$A$87:$B$102, 2, FALSE) = G$2, "X", ""), "") -> X | H4: =IFERROR(IF( VLOOKUP($B4, Todo!$A$103:$B$120, 2, FALSE) = H$2, "X", ""), "") | I4: =IFERROR(IF( VLOOKUP($B4,Todo!$A$121:$B$130, 2, FALSE) = I$2, "X", ""), "") | J4: =IFERROR(IF( VLOOKUP($B4,Todo!$A$131:$B$152, 2, FALSE) = J$2, "X", ""), "") -> X | K4: =IFERROR(IF( VLOOKUP($B4,Todo!$A$153:$B$170, 2, FALSE) = K$2, "X", ""), "") -> X | L4: =IFERROR(IF( VLOOKUP($B4,Todo!$A$172:$B$238, 2, FALSE) = L$2, "X", ""), "") -> X
A5: Greg Wirt discuten | B5: =VLOOKUP(A5, 'Asignar letras'!$A$2:$B$100, 2, 0) -> E48 | C5: =IFERROR(IF( VLOOKUP(B5, Todo!$A$4:$B$28, 2, FALSE) = C$2, "X", ""), "") -> X | D5: =IFERROR(IF( VLOOKUP($B5, Todo!$A$29:$B$46, 2, FALSE) = D$2, "X", ""), "") -> X | E5: =IFERROR(IF( VLOOKUP($B5, Todo!$A$47:$B$67, 2, FALSE) = E$2, "X", ""), "") | F5: =IFERROR(IF( VLOOKUP($B5, Todo!$A$68:$B$86, 2, FALSE) = F$2, "X", ""), "") | G5: =IFERROR(IF( VLOOKUP($B5, Todo!$A$87:$B$102, 2, FALSE) = G$2, "X", ""), "") -> X | H5: =IFERROR(IF( VLOOKUP($B5, Todo!$A$103:$B$120, 2, FALSE) = H$2, "X", ""), "") -> X | I5: =IFERROR(IF( VLOOKUP($B5,Todo!$A$121:$B$130, 2, FALSE) = I$2, "X", ""), "") -> X | J5: =IFERROR(IF( VLOOKUP($B5,Todo!$A$131:$B$152, 2, FALSE) = J$2, "X", ""), "") | K5: =IFERROR(IF( VLOOKUP($B5,Todo!$A$153:$B$170, 2, FALSE) = K$2, "X", ""), "") -> X | L5: =IFERROR(IF( VLOOKUP($B5,Todo!$A$172:$B$238, 2, FALSE) = L$2, "X", ""), "") -> X
A6: Beatríz aparece | B6: =VLOOKUP(A6, 'Asignar letras'!$A$2:$B$100, 2, 0) -> E8 | C6: =IFERROR(IF( VLOOKUP(B6, Todo!$A$4:$B$28, 2, FALSE) = C$2, "X", ""), "") -> X | D6: =IFERROR(IF( VLOOKUP($B6, Todo!$A$29:$B$46, 2, FALSE) = D$2, "X", ""), "") -> X | E6: =IFERROR(IF( VLOOKUP($B6, Todo!$A$47:$B$67, 2, FALSE) = E$2, "X", ""), "") | F6: =IFERROR(IF( VLOOKUP($B6, Todo!$A$68:$B$86, 2, FALSE) = F$2, "X", ""), "") -> X | G6: =IFERROR(IF( VLOOKUP($B6, Todo!$A$87:$B$102, 2, FALSE) = G$2, "X", ""), "") | H6: =IFERROR(IF( VLOOKUP($B6, Todo!$A$103:$B$120, 2, FALSE) = H$2, "X", ""), "") | I6: =IFERROR(IF( VLOOKUP($B6,Todo!$A$121:$B$130, 2, FALSE) = I$2, "X", ""), "") | J6: =IFERROR(IF( VLOOKUP($B6,Todo!$A$131:$B$152, 2, FALSE) = J$2, "X", ""), "") | K6: =IFERROR(IF( VLOOKUP($B6,Todo!$A$153:$B$170, 2, FALSE) = K$2, "X", ""), "") | L6: =IFERROR(IF( VLOOKUP($B6,Todo!$A$172:$B$238, 2, FALSE) = L$2, "X", ""), "")
A7: Greg Wirt discuten | B7: =VLOOKUP(A7, 'Asignar letras'!$A$2:$B$100, 2, 0) -> E48 | C7: =IFERROR(IF( VLOOKUP(B7, Todo!$A$4:$B$28, 2, FALSE) = C$2, "X", ""), "") -> X | D7: =IFERROR(IF( VLOOKUP($B7, Todo!$A$29:$B$46, 2, FALSE) = D$2, "X", ""), "") -> X | E7: =IFERROR(IF( VLOOKUP($B7, Todo!$A$47:$B$67, 2, FALSE) = E$2, "X", ""), "") | F7: =IFERROR(IF( VLOOKUP($B7, Todo!$A$68:$B$86, 2, FALSE) = F$2, "X", ""), "") | G7: =IFERROR(IF( VLOOKUP($B7, Todo!$A$87:$B$102, 2, FALSE) = G$2, "X", ""), "") -> X | H7: =IFERROR(IF( VLOOKUP($B7, Todo!$A$103:$B$120, 2, FALSE) = H$2, "X", ""), "") -> X | I7: =IFERROR(IF( VLOOKUP($B7,Todo!$A$121:$B$130, 2, FALSE) = I$2, "X", ""), "") -> X | J7: =IFERROR(IF( VLOOKUP($B7,Todo!$A$131:$B$152, 2, FALSE) = J$2, "X", ""), "") | K7: =IFERROR(IF( VLOOKUP($B7,Todo!$A$153:$B$170, 2, FALSE) = K$2, "X", ""), "") -> X | L7: =IFERROR(IF( VLOOKUP($B7,Todo!$A$172:$B$238, 2, FALSE) = L$2, "X", ""), "") -> X
A8: Leñador aparece | B8: =VLOOKUP(A8, 'Asignar letras'!$A$2:$B$100, 2, 0) -> E63 | C8: =IFERROR(IF( VLOOKUP(B8, Todo!$A$4:$B$28, 2, FALSE) = C$2, "X", ""), "") -> X | D8: =IFERROR(IF( VLOOKUP($B8, Todo!$A$29:$B$46, 2, FALSE) = D$2, "X", ""), "") | E8: =IFERROR(IF( VLOOKUP($B8, Todo!$A$47:$B$67, 2, FALSE) = E$2, "X", ""), "") | F8: =IFERROR(IF( VLOOKUP($B8, Todo!$A$68:$B$86, 2, FALSE) = F$2, "X", ""), "") -> X | G8: =IFERROR(IF( VLOOKUP($B8, Todo!$A$87:$B$102, 2, FALSE) = G$2, "X", ""), "") | H8: =IFERROR(IF( VLOOKUP($B8, Todo!$A$103:$B$120, 2, FALSE) = H$2, "X", ""), "") | I8: =IFERROR(IF( VLOOKUP($B8,Todo!$A$121:$B$130, 2, FALSE) = I$2, "X", ""), "") -> X | J8: =IFERROR(IF( VLOOKUP($B8,Todo!$A$131:$B$152, 2, FALSE) = J$2, "X", ""), "") -> X | K8: =IFERROR(IF( VLOOKUP($B8,Todo!$A$153:$B$170, 2, FALSE) = K$2, "X", ""), "") | L8: =IFERROR(IF( VLOOKUP($B8,Todo!$A$172:$B$238, 2, FALSE) = L$2, "X", ""), "") -> X
A9: Leñador advierte | B9: =VLOOKUP(A9, 'Asignar letras'!$A$2:$B$100, 2, 0) -> E62 | C9: =IFERROR(IF( VLOOKUP(B9, Todo!$A$4:$B$28, 2, FALSE) = C$2, "X", ""), "") -> X | D9: =IFERROR(IF( VLOOKUP($B9, Todo!$A$29:$B$46, 2, FALSE) = D$2, "X", ""), "") | E9: =IFERROR(IF( VLOOKUP($B9, Todo!$A$47:$B$67, 2, FALSE) = E$2, "X", ""), "") | F9: =IFERROR(IF( VLOOKUP($B9, Todo!$A$68:$B$86, 2, FALSE) = F$2, "X", ""), "") | G9: =IFERROR(IF( VLOOKUP($B9, Todo!$A$87:$B$102, 2, FALSE) = G$2, "X", ""), "") | H9: =IFERROR(IF( VLOOKUP($B9, Todo!$A$103:$B$120, 2, FALSE) = H$2, "X", ""), "") | I9: =IFERROR(IF( VLOOKUP($B9,Todo!$A$121:$B$130, 2, FALSE) = I$2, "X", ""), "") -> X | J9: =IFERROR(IF( VLOOKUP($B9,Todo!$A$131:$B$152, 2, FALSE) = J$2, "X", ""), "") | K9: =IFERROR(IF( VLOOKUP($B9,Todo!$A$153:$B$170, 2, FALSE) = K$2, "X", ""), "") | L9: =IFERROR(IF( VLOOKUP($B9,Todo!$A$172:$B$238, 2, FALSE) = L$2, "X", ""), "")
A10: Leñador guía | B10: =VLOOKUP(A10, 'Asignar letras'!$A$2:$B$100, 2, 0) -> E65 | C10: =IFERROR(IF( VLOOKUP(B10, Todo!$A$4:$B$28, 2, FALSE) = C$2, "X", ""), "") -> X | D10: =IFERROR(IF( VLOOKUP($B10, Todo!$A$29:$B$46, 2, FALSE) = D$2, "X", ""), "") | E10: =IFERROR(IF( VLOOKUP($B10, Todo!$A$47:$B$67, 2, FALSE) = E$2, "X", ""), "") | F10: =IFERROR(IF( VLOOKUP($B10, Todo!$A$68:$B$86, 2, FALSE) = F$2, "X", ""), "") | G10: =IFERROR(IF( VLOOKUP($B10, Todo!$A$87:$B$102, 2, FALSE) = G$2, "X", ""), "") | H10: =IFERROR(IF( VLOOKUP($B10, Todo!$A$103:$B$120, 2, FALSE) = H$2, "X", ""), "") | I10: =IFERROR(IF( VLOOKUP($B10,Todo!$A$121:$B$130, 2, FALSE) = I$2, "X", ""), "") | J10: =IFERROR(IF( VLOOKUP($B10,Todo!$A$131:$B$152, 2, FALSE) = J$2, "X", ""), "") | K10: =IFERROR(IF( VLOOKUP($B10,Todo!$A$153:$B$170, 2, FALSE) = K$2, "X", ""), "") | L10: =IFERROR(IF( VLOOKUP($B10,Todo!$A$172:$B$238, 2, FALSE) = L$2, "X", ""), "")
A11: Leñador advierte | B11: =VLOOKUP(A11, 'Asignar letras'!$A$2:$B$100, 2, 0) -> E62 | C11: =IFERROR(IF( VLOOKUP(B11, Todo!$A$4:$B$28, 2, FALSE) = C$2, "X", ""), "") -> X | D11: =IFERROR(IF( VLOOKUP($B11, Todo!$A$29:$B$46, 2, FALSE) = D$2, "X", ""), "") | E11: =IFERROR(IF( VLOOKUP($B11, Todo!$A$47:$B$67, 2, FALSE) = E$2, "X", ""), "") | F11: =IFERROR(IF( VLOOKUP($B11, Todo!$A$68:$B$86, 2, FALSE) = F$2, "X", ""), "") | G11: =IFERROR(IF( VLOOKUP($B11, Todo!$A$87:$B$102, 2, FALSE) = G$2, "X", ""), "") | H11: =IFERROR(IF( VLOOKUP($B11, Todo!$A$103:$B$120, 2, FALSE) = H$2, "X", ""), "") | I11: =IFERROR(IF( VLOOKUP($B11,Todo!$A$121:$B$130, 2, FALSE) = I$2, "X", ""), "") -> X | J11: =IFERROR(IF( VLOOKUP($B11,Todo!$A$131:$B$152, 2, FALSE) = J$2, "X", ""), "") | K11: =IFERROR(IF( VLOOKUP($B11,Todo!$A$153:$B$170, 2, FALSE) = K$2, "X", ""), "") | L11: =IFERROR(IF( VLOOKUP($B11,Todo!$A$172:$B$238, 2, FALSE) = L$2, "X", ""), "")
A12: Wirt se preocupa | B12: =VLOOKUP(A12, 'Asignar letras'!$A$2:$B$100, 2, 0) -> E97 | C12: =IFERROR(IF( VLOOKUP(B12, Todo!$A$4:$B$28, 2, FALSE) = C$2, "X", ""), "") -> X | D12: =IFERROR(IF( VLOOKUP($B12, Todo!$A$29:$B$46, 2, FALSE) = D$2, "X", ""), "") | E12: =IFERROR(IF( VLOOKUP($B12, Todo!$A$47:$B$67, 2, FALSE) = E$2, "X", ""), "") | F12: =IFERROR(IF( VLOOKUP($B12, Todo!$A$68:$B$86, 2, FALSE) = F$2, "X", ""), "") -> X | G12: =IFERROR(IF( VLOOKUP($B12, Todo!$A$87:$B$102, 2, FALSE) = G$2, "X", ""), "") -> X | H12: =IFERROR(IF( VLOOKUP($B12, Todo!$A$103:$B$120, 2, FALSE) = H$2, "X", ""), "") | I12: =IFERROR(IF( VLOOKUP($B12,Todo!$A$121:$B$130, 2, FALSE) = I$2, "X", ""), "") | J12: =IFERROR(IF( VLOOKUP($B12,Todo!$A$131:$B$152, 2, FALSE) = J$2, "X", ""), "") -> X | K12: =IFERROR(IF( VLOOKUP($B12,Todo!$A$153:$B$170, 2, FALSE) = K$2, "X", ""), "") -> X | L12: =IFERROR(IF( VLOOKUP($B12,Todo!$A$172:$B$238, 2, FALSE) = L$2, "X", ""), "") -> X
A13: Greg Wirt discuten | B13: =VLOOKUP(A13, 'Asignar letras'!$A$2:$B$100, 2, 0) -> E48 | C13: =IFERROR(IF( VLOOKUP(B13, Todo!$A$4:$B$28, 2, FALSE) = C$2, "X", ""), "") -> X | D13: =IFERROR(IF( VLOOKUP($B13, Todo!$A$29:$B$46, 2, FALSE) = D$2, "X", ""), "") -> X | E13: =IFERROR(IF( VLOOKUP($B13, Todo!$A$47:$B$67, 2, FALSE) = E$2, "X", ""), "") | F13: =IFERROR(IF( VLOOKUP($B13, Todo!$A$68:$B$86, 2, FALSE) = F$2, "X", ""), "") | G13: =IFERROR(IF( VLOOKUP($B13, Todo!$A$87:$B$102, 2, FALSE) = G$2, "X", ""), "") -> X | H13: =IFERROR(IF( VLOOKUP($B13, Todo!$A$103:$B$120, 2, FALSE) = H$2, "X", ""), "") -> X | I13: =IFERROR(IF( VLOOKUP($B13,Todo!$A$121:$B$130, 2, FALSE) = I$2, "X", ""), "") -> X | J13: =IFERROR(IF( VLOOKUP($B13,Todo!$A$131:$B$152, 2, FALSE) = J$2, "X", ""), "") | K13: =IFERROR(IF( VLOOKUP($B13,Todo!$A$153:$B$170, 2, FALSE) = K$2, "X", ""), "") -> X | L13: =IFERROR(IF( VLOOKUP($B13,Todo!$A$172:$B$238, 2, FALSE) = L$2, "X", ""), "") -> X
A14: Leñador advierte | B14: =VLOOKUP(A14, 'Asignar letras'!$A$2:$B$100, 2, 0) -> E62 | C14: =IFERROR(IF( VLOOKUP(B14, Todo!$A$4:$B$28, 2, FALSE) = C$2, "X", ""), "") -> X | D14: =IFERROR(IF( VLOOKUP($B14, Todo!$A$29:$B$46, 2, FALSE) = D$2, "X", ""), "") | E14: =IFERROR(IF( VLOOKUP($B14, Todo!$A$47:$B$67, 2, FALSE) = E$2, "X", ""), "") | F14: =IFERROR(IF( VLOOKUP($B14, Todo!$A$68:$B$86, 2, FALSE) = F$2, "X", ""), "") | G14: =IFERROR(IF( VLOOKUP($B14, Todo!$A$87:$B$102, 2, FALSE) = G$2, "X", ""), "") | H14: =IFERROR(IF( VLOOKUP($B14, Todo!$A$103:$B$120, 2, FALSE) = H$2, "X", ""), "") | I14: =IFERROR(IF( VLOOKUP($B14,Todo!$A$121:$B$130, 2, FALSE) = I$2, "X", ""), "") -> X | J14: =IFERROR(IF( VLOOKUP($B14,Todo!$A$131:$B$152, 2, FALSE) = J$2, "X", ""), "") | K14: =IFERROR(IF( VLOOKUP($B14,Todo!$A$153:$B$170, 2, FALSE) = K$2, "X", ""), "") | L14: =IFERROR(IF( VLOOKUP($B14,Todo!$A$172:$B$238, 2, FALSE) = L$2, "X", ""), "")
... A229: Jason aparece | B229: =VLOOKUP(A229, 'Asignar letras'!$A$2:$B$100, 2, 0) -> E61 | C229: =IFERROR(IF( VLOOKUP(B229, Todo!$A$4:$B$28, 2, FALSE) = C$2, "X", ""), "") | D229: =IFERROR(IF( VLOOKUP($B229, Todo!$A$29:$B$46, 2, FALSE) = D$2, "X", ""), "") | E229: =IFERROR(IF( VLOOKUP($B229, Todo!$A$47:$B$67, 2, FALSE) = E$2, "X", ""), "") | F229: =IFERROR(IF( VLOOKUP($B229, Todo!$A$68:$B$86, 2, FALSE) = F$2, "X", ""), "") | G229: =IFERROR(IF( VLOOKUP($B229, Todo!$A$87:$B$102, 2, FALSE) = G$2, "X", ""), "") | H229: =IFERROR(IF( VLOOKUP($B229, Todo!$A$103:$B$120, 2, FALSE) = H$2, "X", ""), "") | I229: =IFERROR(IF( VLOOKUP($B229,Todo!$A$121:$B$130, 2, FALSE) = I$2, "X", ""), "") | J229: =IFERROR(IF( VLOOKUP($B229,Todo!$A$131:$B$152, 2, FALSE) = J$2, "X", ""), "") | K229: =IFERROR(IF( VLOOKUP($B229,Todo!$A$153:$B$170, 2, FALSE) = K$2, "X", ""), "") | L229: =IFERROR(IF( VLOOKUP($B229,Todo!$A$172:$B$238, 2, FALSE) = L$2, "X", ""), "") -> X
A230: Wirt se prepara | B230: =VLOOKUP(A230, 'Asignar letras'!$A$2:$B$100, 2, 0) -> E98 | C230: =IFERROR(IF( VLOOKUP(B230, Todo!$A$4:$B$28, 2, FALSE) = C$2, "X", ""), "") | D230: =IFERROR(IF( VLOOKUP($B230, Todo!$A$29:$B$46, 2, FALSE) = D$2, "X", ""), "") -> X | F230: =IFERROR(IF( VLOOKUP($B230, Todo!$A$68:$B$86, 2, FALSE) = F$2, "X", ""), "") | G230: =IFERROR(IF( VLOOKUP($B230, Todo!$A$87:$B$102, 2, FALSE) = G$2, "X", ""), "") | H230: =IFERROR(IF( VLOOKUP($B230, Todo!$A$103:$B$120, 2, FALSE) = H$2, "X", ""), "") | I230: =IFERROR(IF( VLOOKUP($B230,Todo!$A$121:$B$130, 2, FALSE) = I$2, "X", ""), "") | J230: =IFERROR(IF( VLOOKUP($B230,Todo!$A$131:$B$152, 2, FALSE) = J$2, "X", ""), "") | K230: =IFERROR(IF( VLOOKUP($B230,Todo!$A$153:$B$170, 2, FALSE) = K$2, "X", ""), "") | L230: =IFERROR(IF( VLOOKUP($B230,Todo!$A$172:$B$238, 2, FALSE) = L$2, "X", ""), "") -> X
A231: Tiempo avanza | B231: =VLOOKUP(A231, 'Asignar letras'!$A$2:$B$100, 2, 0) -> E81 | C231: =IFERROR(IF( VLOOKUP(B231, Todo!$A$4:$B$28, 2, FALSE) = C$2, "X", ""), "") | D231: =IFERROR(IF( VLOOKUP($B231, Todo!$A$29:$B$46, 2, FALSE) = D$2, "X", ""), "") | F231: =IFERROR(IF( VLOOKUP($B231, Todo!$A$68:$B$86, 2, FALSE) = F$2, "X", ""), "") | G231: =IFERROR(IF( VLOOKUP($B231, Todo!$A$87:$B$102, 2, FALSE) = G$2, "X", ""), "") | H231: =IFERROR(IF( VLOOKUP($B231, Todo!$A$103:$B$120, 2, FALSE) = H$2, "X", ""), "") | I231: =IFERROR(IF( VLOOKUP($B231,Todo!$A$121:$B$130, 2, FALSE) = I$2, "X", ""), "") | J231: =IFERROR(IF( VLOOKUP($B231,Todo!$A$131:$B$152, 2, FALSE) = J$2, "X", ""), "") | K231: =IFERROR(IF( VLOOKUP($B231,Todo!$A$153:$B$170, 2, FALSE) = K$2, "X", ""), "") | L231: =IFERROR(IF( VLOOKUP($B231,Todo!$A$172:$B$238, 2, FALSE) = L$2, "X", ""), "") -> X

Sheet DatosH
A1: Episodios\Actividades | C1: E58 | D1: E97 | E1: E48 | F1: E8 | G1: E48 | H1: E63 | I1: E62 | J1: E65 | K1: E62 | L1: E97 | M1: E48 | N1: E62 | O1: E35 | P1: E97 | Q1: E34 | R1: E49 | S1: E51 | T1: E67 | U1: E51 | V1: E63 | W1: E62 | X1: E48 | Y1: E62 | Z1: E96 | AA1: E51 | AB1: E35 | AC1: E48 | AD1: E8 | AE1: E11 | AF1: E51 | AG1: E91 | AH1: E34 | AI1: E11 | AJ1: E18 | AK1: E98 | AL1: E96 | AM1: E51 | AN1: E18 | AO1: E76 | AP1: E29 | AQ1: E96 | AR1: E92 | AS1: E11 | AT1: E35 | AU1: E30 | AV1: E40 | AW1: E11 | AX1: E84 | AY1: E35 | AZ1: E34 | BA1: E87 | BB1: E9 | BC1: E84 | BD1: E72 | BE1: E71 | BF1: E73 | BG1: E35 | BH1: E33 | BI1: E30 | BJ1: E59 | BK1: E60 | BL1: E51 | BM1: E76 | BN1: E39 | BO1: E63 | BP1: E56 | BQ1: E8 | BR1: E28 | BS1: E42 | BT1: E75 | BU1: E76 | BV1: E63 | BW1: E76 | BX1: E97 | BY1: E88 | BZ1: E77 | CA1: E10 | CB1: E63 | CC1: E52 | CD1: E51 | CE1: E18 | CF1: E22 | CG1: E17 | CH1: E3 | CI1: E97 | CJ1: E84 | CK1: E85 | CL1: E25 | CM1: E84 | CN1: E26 | CO1: E84 | CP1: E72 | CQ1: E4 | CR1: E6 | CS1: E30 | CT1: E51 | CU1: E84 | CV1: E48 | CW1: E54 | CX1: E6 | CY1: E11 | CZ1: E41 | DA1: E12 | DB1: E50 | DC1: E1 | DD1: E7 | DE1: E38 | DF1: E55 | DG1: E13 | DH1: E2 | DI1: E51 | DJ1: E56 | DK1: E48 | DL1: E57 | DM1: E63 | DN1: E62 | DO1: E93 | DP1: E62 | DQ1: E51 | DR1: E18 | DS1: E19 | DT1: E50 | DU1: E34 | DV1: E24 | DW1: E23 | DX1: E72 | DY1: E54 | DZ1: E71 | EA1: E74 | EB1: E38 | EC1: E39 | ED1: E34 | EE1: E72 | EF1: E71 | EG1: E45 | EH1: E70 | EI1: E51 | EJ1: E39 | EK1: E56 | EL1: E97 | EM1: E18 | EN1: E63 | EO1: E69 | EP1: E56 | EQ1: E97 | ER1: E99 | ES1: E48 | ET1: E46 | EU1: E37 | EV1: E75 | EW1: E76 | EX1: E30 | EY1: E70 | EZ1: E15 | FA1: E36 | FB1: E47 | FC1: E18 | FD1: E31 | FE1: E97 | FF1: E95 | FG1: E89 | FH1: E8 | FI1: E82 | FJ1: E97 | FK1: E98 | FL1: E27 | FM1: E97 | FN1: E94 | FO1: E97 | FP1: E48 | FQ1: E97 | FR1: E48 | FS1: E51 | FT1: E53 | FU1: E79 | FV1: E94 | FW1: E61 | FX1: E97 | FY1: E80 | FZ1: E95 | GA1: E98 | GB1: E94 | GC1: E78 | GD1: E51 | GE1: E97 | GF1: E48 | GG1: E44 | GH1: E81 | GI1: E97 | GJ1: E98 | GK1: E95 | GL1: E14 | GM1: E27 | GN1: E21 | GO1: E20 | GP1: E32 | GQ1: E31 | GR1: E83 | GS1: E84 | GT1: E11 | GU1: E86 | GV1: E63 | GW1: E68 | GX1: E18 | GY1: E16 | GZ1: E20 | HA1: E64 | HB1: E20 | HC1: E66 | HD1: E32 | HE1: E97 | HF1: E18 | HG1: E20 | HH1: E98 | HI1: E90 | HJ1: E93 | HK1: E20 | HL1: E98 | HM1: E43 | HN1: E20 | HO1: E66 | HP1: E82 | HQ1: E98 | HR1: E46 | HS1: E81 | HT1: E79 | HU1: E61 | HV1: E98 | HW1: E81
B2: Episodio 1 | C2: X | D2: X | E2: X | F2: X | G2: X | H2: X | I2: X | J2: X | K2: X | L2: X | M2: X | N2: X | O2: X | P2: X | Q2: X | R2: X | S2: X | T2: X | U2: X | V2: X | W2: X | X2: X | Y2: X | Z2: X | AA2: X | AB2: X | AC2: X | AD2: X | AF2: X | AH2: X | AL2: X | AM2: X | AQ2: X | AT2: X | AY2: X | AZ2: X | BG2: X | BL2: X | BO2: X | BQ2: X | BV2: X | BX2: X | CB2: X | CD2: X | CI2: X | CT2: X | CV2: X | DI2: X | DK2: X | DM2: X | DN2: X | DP2: X | DQ2: X | DU2: X | ED2: X | EI2: X | EL2: X | EN2: X | EQ2: X | ES2: X | FE2: X | FH2: X | FJ2: X | FM2: X | FO2: X | FP2: X | FQ2: X | FR2: X | FS2: X | FX2: X | GD2: X | GE2: X | GF2: X | GI2: X | GV2: X | HE2: X
B3: Episodio 2 | E3: X | F3: X | G3: X | M3: X | O3: X | Q3: X | S3: X | U3: X | X3: X | Z3: X | AA3: X | AB3: X | AC3: X | AD3: X | AE3: X | AF3: X | AG3: X | AH3: X | AI3: X | AJ3: X | AK3: X | AL3: X | AM3: X | AN3: X | AO3: X | AP3: X | AQ3: X | AR3: X | AS3: X | AT3: X | AW3: X | AY3: X | AZ3: X | BG3: X | BL3: X | BM3: X | BQ3: X | BU3: X | BW3: X | CD3: X | CE3: X | CT3: X | CV3: X | CY3: X | DI3: X | DK3: X | DQ3: X | DR3: X | DU3: X | ED3: X | EI3: X | EM3: X | ES3: X | EW3: X | FC3: X | FH3: X | FK3: X | FP3: X | FR3: X | FS3: X | GA3: X | GD3: X | GF3: X | GJ3: X | GT3: X | GX3: X | HF3: X | HH3: X | HL3: X | HQ3: X | HV3: X
B4: Episodio 3 | O4: X | Q4: X | S4: X | U4: X | AA4: X | AB4: X | AE4: X | AF4: X | AH4: X | AI4: X | AM4: X | AO4: X | AS4: X | AT4: X | AU4: X | AV4: X | AW4: X | AX4: X | AY4: X | AZ4: X | BA4: X | BB4: X | BC4: X | BD4: X | BE4: X | BF4: X | BG4: X | BH4: X | BI4: X | BJ4: X | BK4: X | BL4: X | BM4: X | BN4: X | BU4: X | BW4: X | CD4: X | CJ4: X | CM4: X | CO4: X | CP4: X | CS4: X | CT4: X | CU4: X | CY4: X | DI4: X | DQ4: X | DU4: X | DX4: X | DZ4: X | EC4: X | ED4: X | EE4: X | EF4: X | EI4: X | EJ4: X | EW4: X | EX4: X | FS4: X | GD4: X | GS4: X | GT4: X
B5: Episodio 4 | D5: X | F5: X | H5: X | L5: X | P5: X | S5: X | U5: X | V5: X | AA5: X | AD5: X | AF5: X | AJ5: X | AM5: X | AN5: X | AO5: X | BL5: X | BM5: X | BO5: X | BP5: X | BQ5: X | BR5: X | BS5: X | BT5: X | BU5: X | BV5: X | BW5: X | BX5: X | BY5: X | BZ5: X | CA5: X | CB5: X | CC5: X | CD5: X | CE5: X | CF5: X | CG5: X | CI5: X | CT5: X | DI5: X | DJ5: X | DM5: X | DQ5: X | DR5: X | EI5: X | EK5: X | EL5: X | EM5: X | EN5: X | EP5: X | EQ5: X | EV5: X | EW5: X | FC5: X | FE5: X | FH5: X | FJ5: X | FM5: X | FO5: X | FQ5: X | FS5: X | FX5: X | GD5: X | GE5: X | GI5: X | GV5: X | GX5: X | HE5: X | HF5: X
B6: Episodio 5 | D6: X | E6: X | G6: X | L6: X | M6: X | O6: X | P6: X | S6: X | U6: X | X6: X | AA6: X | AB6: X | AC6: X | AF6: X | AM6: X | AT6: X | AX6: X | AY6: X | BC6: X | BD6: X | BG6: X | BL6: X | BN6: X | BX6: X | CD6: X | CH6: X | CI6: X | CJ6: X | CK6: X | CL6: X | CM6: X | CN6: X | CO6: X | CP6: X | CQ6: X | CT6: X | CU6: X | CV6: X | DI6: X | DK6: X | DQ6: X | DX6: X | EC6: X | EE6: X | EI6: X | EJ6: X | EL6: X | EQ6: X | ES6: X | FE6: X | FJ6: X | FM6: X | FO6: X | FP6: X | FQ6: X | FR6: X | FS6: X | FX6: X | GD6: X | GE6: X | GF6: X | GI6: X | GS6: X | HE6: X
B7: Episodio 6 | E7: X | G7: X | M7: X | S7: X | U7: X | X7: X | AA7: X | AC7: X | AE7: X | AF7: X | AI7: X | AM7: X | AS7: X | AU7: X | AW7: X | AX7: X | BC7: X | BI7: X | BL7: X | CD7: X | CJ7: X | CM7: X | CO7: X | CR7: X | CS7: X | CT7: X | CU7: X | CV7: X | CW7: X | CX7: X | CY7: X | CZ7: X | DA7: X | DB7: X | DC7: X | DD7: X | DE7: X | DF7: X | DG7: X | DH7: X | DI7: X | DK7: X | DQ7: X | DT7: X | DY7: X | EB7: X | EI7: X | ES7: X | EX7: X | FP7: X | FR7: X | FS7: X | GD7: X | GF7: X | GS7: X | GT7: X
B8: Episodio 7 | E8: X | G8: X | H8: X | I8: X | K8: X | M8: X | N8: X | S8: X | U8: X | V8: X | W8: X | X8: X | Y8: X | AA8: X | AC8: X | AF8: X | AJ8: X | AM8: X | AN8: X | BL8: X | BO8: X | BP8: X | BV8: X | CB8: X | CD8: X | CE8: X | CT8: X | CV8: X | DI8: X | DJ8: X | DK8: X | DL8: X | DM8: X | DN8: X | DO8: X | DP8: X | DQ8: X | DR8: X | DS8: X | EI8: X | EK8: X | EM8: X | EN8: X | EP8: X | ES8: X | FC8: X | FP8: X | FR8: X | FS8: X | GD8: X | GF8: X | GV8: X | GX8: X | HF8: X | HJ8: X
B9: Episodio 8 | D9: X | H9: X | L9: X | P9: X | Q9: X | S9: X | U9: X | V9: X | AA9: X | AF9: X | AH9: X | AJ9: X | AM9: X | AN9: X | AZ9: X | BD9: X | BE9: X | BL9: X | BN9: X | BO9: X | BP9: X | BV9: X | BX9: X | CB9: X | CD9: X | CE9: X | CI9: X | CP9: X | CT9: X | CW9: X | DB9: X | DE9: X | DI9: X | DJ9: X | DM9: X | DQ9: X | DR9: X | DT9: X | DU9: X | DV9: X | DW9: X | DX9: X | DY9: X | DZ9: X | EA9: X | EB9: X | EC9: X | ED9: X | EE9: X | EF9: X | EG9: X | EH9: X | EI9: X | EJ9: X | EK9: X | EL9: X | EM9: X | EN9: X | EO9: X | EP9: X | EQ9: X | EY9: X | FC9: X | FE9: X | FJ9: X | FM9: X | FO9: X | FQ9: X | FS9: X | FX9: X | GD9: X | GE9: X | GI9: X | GV9: X | GX9: X | HE9: X | HF9: X
B10: Episodio 9 | D10: X | E10: X | G10: X | L10: X | M10: X | P10: X | X10: X | AC10: X | AJ10: X | AN10: X | AO10: X | AU10: X | BI10: X | BM10: X | BP10: X | BT10: X | BU10: X | BW10: X | BX10: X | CE10: X | CI10: X | CS10: X | CV10: X | DJ10: X | DK10: X | DR10: X | EH10: X | EK10: X | EL10: X | EM10: X | EP10: X | EQ10: X | ER10: X | ES10: X | ET10: X | EU10: X | EV10: X | EW10: X | EX10: X | EY10: X | EZ10: X | FA10: X | FB10: X | FC10: X | FD10: X | FE10: X | FF10: X | FG10: X | FJ10: X | FM10: X | FO10: X | FP10: X | FQ10: X | FR10: X | FX10: X | FZ10: X | GE10: X | GF10: X | GI10: X | GK10: X | GQ10: X | GX10: X | HE10: X | HF10: X | HR10: X
B11: Episodio 10 | D11: X | E11: X | G11: X | H11: X | L11: X | M11: X | P11: X | S11: X | U11: X | V11: X | X11: X | AA11: X | AC11: X | AE11: X | AF11: X | AI11: X | AJ11: X | AK11: X | AM11: X | AN11: X | AS11: X | AW11: X | AX11: X | BC11: X | BL11: X | BO11: X | BV11: X | BX11: X | CB11: X | CD11: X | CE11: X | CI11: X | CJ11: X | CM11: X | CO11: X | CT11: X | CU11: X | CV11: X | CY11: X | DI11: X | DK11: X | DM11: X | DO11: X | DQ11: X | DR11: X | EI11: X | EL11: X | EM11: X | EN11: X | EQ11: X | ES11: X | ET11: X | FC11: X | FD11: X | FE11: X | FF11: X | FI11: X | FJ11: X | FK11: X | FL11: X | FM11: X | FN11: X | FO11: X | FP11: X | FQ11: X | FR11: X | FS11: X | FT11: X | FU11: X | FV11: X | FW11: X | FX11: X | FY11: X | FZ11: X | GA11: X | GB11: X | GC11: X | GD11: X | GE11: X | GF11: X | GG11: X | GH11: X | GI11: X | GJ11: X | GK11: X | GL11: X | GM11: X | GN11: X | GO11: X | GP11: X | GQ11: X | GR11: X | GS11: X | GT11: X | GU11: X | GV11: X | GW11: X | GX11: X | GY11: X | GZ11: X | HA11: X | HB11: X | HC11: X | HD11: X | HE11: X | HF11: X | HG11: X | HH11: X | HI11: X | HJ11: X | HK11: X | HL11: X | HM11: X | HN11: X | HO11: X | HP11: X | HQ11: X | HR11: X | HS11: X | HT11: X | HU11: X | HV11: X | HW11: X

Sheet Todo
B1: Serie: | C1: Más allá del Jardín
C3: Qué ocurre | D3: Timestamp | G3: A entonces B, Tal Ventana (Tamaño de la ventana) | L3: Dudas: | M3: El libro dice que support es: "De todos los casos… ¿en cuántos aparecen X y Y juntos?"
A4: =VLOOKUP(C4, 'Asignar letras'!$A$2:$B$100, 2, 0) -> E58 | B4: Episodio 1 | C4: Greg y Wirt Vagan | D4: 6.9444444e-05 | M4: Con "todos los casos" se refiere a todas las ventanas que se forman de 2 + Ventanas de 3 + Ventanas de 4… etc--
A5: =VLOOKUP(C5, 'Asignar letras'!$A$2:$B$100, 2, 0) -> E97 | B5: Episodio 1 | C5: Wirt se preocupa | D5: 0.00021990741 | G5: Leer reglas de asociación.
A6: =VLOOKUP(C6, 'Asignar letras'!$A$2:$B$100, 2, 0) -> E48 | B6: Episodio 1 | C6: Greg Wirt discuten | D6: 0.0030324074 | G6: No hacer reglas compuestas. | M6: No entendí la diferencia entre: | P6: Support | Q6: Pag 120
A7: =VLOOKUP(C7, 'Asignar letras'!$A$2:$B$100, 2, 0) -> E8 | B7: Episodio 1 | C7: Beatríz aparece | D7: 0.008125 | G7: Leer y traer preguntas. | P7: Confianza | Q7: Pag 120
A8: =VLOOKUP(C8, 'Asignar letras'!$A$2:$B$100, 2, 0) -> E48 | B8: Episodio 1 | C8: Greg Wirt discuten | D8: 0.0089583333 | G8: Variable de consecuente.
A9: =VLOOKUP(C9, 'Asignar letras'!$A$2:$B$100, 2, 0) -> E63 | B9: Episodio 1 | C9: Leñador aparece | D9: 0.050625 | M9: Entiendo que el "lift" es una medida de qué tan relacionados están
A10: =VLOOKUP(C10, 'Asignar letras'!$A$2:$B$100, 2, 0) -> E62 | B10: Episodio 1 | C10: Leñador advierte | D10: 0.092291667 | N10: 1 = No hay relación | Q10: ¿Tengo que calcular eso también?
A11: =VLOOKUP(C11, 'Asignar letras'!$A$2:$B$100, 2, 0) -> E65 | B11: Episodio 1 | C11: Leñador guía | D11: 0.13395833 | N11: >1 = Hay relación
A12: =VLOOKUP(C12, 'Asignar letras'!$A$2:$B$100, 2, 0) -> E62 | B12: Episodio 1 | C12: Leñador advierte | D12: 0.175625 | N12: <1 = Relación negativa
A13: =VLOOKUP(C13, 'Asignar letras'!$A$2:$B$100, 2, 0) -> E97 | B13: Episodio 1 | C13: Wirt se preocupa | D13: 0.21729167
A14: =VLOOKUP(C14, 'Asignar letras'!$A$2:$B$100, 2, 0) -> E48 | B14: Episodio 1 | C14: Greg Wirt discuten | D14: 0.25895833
A15: =VLOOKUP(C15, 'Asignar letras'!$A$2:$B$100, 2, 0) -> E62 | B15: Episodio 1 | C15: Leñador advierte | D15: 0.300625
A16: =VLOOKUP(C16, 'Asignar letras'!$A$2:$B$100, 2, 0) -> E35 | B16: Episodio 1 | C16: Greg Juega | D16: 0.34229167
A17: =VLOOKUP(C17, 'Asignar letras'!$A$2:$B$100, 2, 0) -> E97 | B17: Episodio 1 | C17: Wirt se preocupa | D17: 0.38395833
A18: =VLOOKUP(C18, 'Asignar letras'!$A$2:$B$100, 2, 0) -> E34 | B18: Episodio 1 | C18: Greg Explora | D18: 0.425625
A19: =VLOOKUP(C19, 'Asignar letras'!$A$2:$B$100, 2, 0) -> E49 | B19: Episodio 1 | C19: Greg Wirt Encuentran un mounstruo | D19: 0.46729167
A20: =VLOOKUP(C20, 'Asignar letras'!$A$2:$B$100, 2, 0) -> E51 | B20: Episodio 1 | C20: Greg Wirt Huyen | D20: 0.50895833
A21: =VLOOKUP(C21, 'Asignar letras'!$A$2:$B$100, 2, 0) -> E67 | B21: Episodio 1 | C21: Leñador Pelea | D21: 0.550625
A22: =VLOOKUP(C22, 'Asignar letras'!$A$2:$B$100, 2, 0) -> E51 | B22: Episodio 1 | C22: Greg Wirt Huyen | D22: 0.59229167
A23: =VLOOKUP(C23, 'Asignar letras'!$A$2:$B$100, 2, 0) -> E63 | B23: Episodio 1 | C23: Leñador aparece | D23: 0.63395833
A24: =VLOOKUP(C24, 'Asignar letras'!$A$2:$B$100, 2, 0) -> E62 | B24: Episodio 1 | C24: Leñador advierte | D24: 0.675625 | G24: Tenemos que terminar con una tabla así: | J24: Pendiente leer lo de la cocina
A25: =VLOOKUP(C25, 'Asignar letras'!$A$2:$B$100, 2, 0) -> E48 | B25: Episodio 1 | C25: Greg Wirt discuten | D25: 0.71729167 | G25: Regla | H25: Tamaño ventana
A26: =VLOOKUP(C26, 'Asignar letras'!$A$2:$B$100, 2, 0) -> E62 | B26: Episodio 1 | C26: Leñador advierte | D26: 0.75895833 | G26: A Entonces B | H26: 3
A27: =VLOOKUP(C27, 'Asignar letras'!$A$2:$B$100, 2, 0) -> E96 | B27: Episodio 1 | C27: Wirt se disculpa | D27: 0.800625 | G27: A Entonces B | H27: N-1
A28: =VLOOKUP(C28, 'Asignar letras'!$A$2:$B$100, 2, 0) -> E51 | B28: Episodio 1 | C28: Greg Wirt Huyen | D28: 0.84229167
A29: =VLOOKUP(C29, 'Asignar letras'!$A$2:$B$100, 2, 0) -> E35 | B29: Episodio 2 | C29: Greg Juega | D29: 0.88395833
A30: =VLOOKUP(C30, 'Asignar letras'!$A$2:$B$100, 2, 0) -> E48 | B30: Episodio 2 | C30: Greg Wirt discuten | D30: 0.925625
A31: =VLOOKUP(C31, 'Asignar letras'!$A$2:$B$100, 2, 0) -> E8 | B31: Episodio 2 | C31: Beatríz aparece | D31: 0.96729167
A32: =VLOOKUP(C32, 'Asignar letras'!$A$2:$B$100, 2, 0) -> E11 | B32: Episodio 2 | C32: Beatríz guía | D32: 1.0089583
A33: =VLOOKUP(C33, 'Asignar letras'!$A$2:$B$100, 2, 0) -> E51 | B33: Episodio 2 | C33: Greg Wirt Huyen | D33: 1.050625
A34: =VLOOKUP(C34, 'Asignar letras'!$A$2:$B$100, 2, 0) -> E91 | B34: Episodio 2 | C34: Wirt explora | D34: 0.0037268519
A35: =VLOOKUP(C35, 'Asignar letras'!$A$2:$B$100, 2, 0) -> E34 | B35: Episodio 2 | C35: Greg explora | D35: 0.0037268519
A36: =VLOOKUP(C36, 'Asignar letras'!$A$2:$B$100, 2, 0) -> E11 | B36: Episodio 2 | C36: Beatríz guía | D36: 0.0056944444
A37: =VLOOKUP(C37, 'Asignar letras'!$A$2:$B$100, 2, 0) -> E18 | B37: Episodio 2 | C37: Bestia aparece
A38: =VLOOKUP(C38, 'Asignar letras'!$A$2:$B$100, 2, 0) -> E98 | B38: Episodio 2 | C38: Wirt se prepara | D38: 0.96729167
A39: =VLOOKUP(C39, 'Asignar letras'!$A$2:$B$100, 2, 0) -> E96 | B39: Episodio 2 | C39: Wirt se disculpa | D39: 1.0089583
A40: =VLOOKUP(C40, 'Asignar letras'!$A$2:$B$100, 2, 0) -> E51 | B40: Episodio 2 | C40: Greg Wirt Huyen | D40: 1.050625
A41: =VLOOKUP(C41, 'Asignar letras'!$A$2:$B$100, 2, 0) -> E18 | B41: Episodio 2 | C41: Bestia aparece | D41: 0.0037268519
...

Sheet Separar predicados
B2: Persona | E2: Seq Num | F2: Cuándo | G2: Qué hizo
A3: Episodio 1 | B3: Greg | C3: Wirt | E3: 1 | F3: 6.9444444e-05 | G3: Vagan | M3: Greg | N3: Wirt | O3: Vagan
B4: Wirt | E4: 2 | F4: 0.00021990741 | G4: preocupa | M4: Wirt | N4: se | O4: preocupa
B5: Greg | C5: Wirt | E5: 3 | F5: 0.0030324074 | G5: discuten | M5: Greg | N5: Wirt | O5: discuten
B6: Beatríz | E6: 4 | F6: 0.008125 | G6: aparece | M6: Beatríz | N6: aparece
B7: Greg | C7: Wirt | E7: 5 | F7: 0.0089583333 | G7: discuten | M7: Greg | N7: Wirt | O7: discuten
B8: Leñador | E8: 6 | G8: aparece | M8: Leñador | N8: aparece
B9: Leñador | E9: 7 | G9: advierte | M9: Leñador | N9: advierte
B10: Leñador | E10: 8 | G10: guía | M10: Leñador | N10: guía
B11: Leñador | E11: 9 | G11: advierte | M11: Leñador | N11: advierte
B12: Wirt | E12: 10 | G12: preocupa | M12: Wirt | N12: se | O12: preocupa
B13: Greg | C13: Wirt | E13: 11 | G13: discuten | M13: Greg | N13: Wirt | O13: discuten
B14: Leñador | E14: 12 | G14: advierte | M14: Leñador | N14: advierte
B15: Greg | E15: 13 | G15: Juega | M15: Greg | N15: Juega
B16: Wirt | E16: 14 | G16: preocupa | M16: Wirt | N16: se | O16: preocupa
B17: Greg | E17: 15 | G17: Explora | M17: Greg | N17: Explora
B18: Greg | C18: Wirt | E18: 16 | G18: Encuentran | M18: Greg | N18: Wirt | O18: Encuentran | P18: un | Q18: mounstruo
B19: Greg | C19: Wirt | E19: 17 | G19: Huyen | M19: Greg | N19: Wirt | O19: Huyen
B20: Leñador | E20: 18 | G20: Pelea | M20: Leñador | N20: Pelea
B21: Greg | C21: Wirt | E21: 19 | G21: Huyen | M21: Greg | N21: Wirt | O21: Huyen
B22: Leñador | E22: 20 | G22: aparece | M22: Leñador | N22: aparece
B23: Leñador | E23: 21 | G23: advierte | M23: Leñador | N23: advierte
B24: Greg | C24: Wirt | E24: 22 | G24: discuten | M24: Greg | N24: Wirt | O24: discuten
B25: Leñador | E25: 23 | G25: advierte | M25: Leñador | N25: advierte
B26: Wirt | E26: 24 | G26: disculpa | M26: Wirt | N26: se | O26: disculpa
B27: Greg | C27: Wirt | E27: 25 | G27: Huyen | M27: Greg | N27: Wirt | O27: Huyen
A28: Episodio 2 | B28: Greg | E28: 26 | G28: Juega | M28: Greg | N28: Juega
B29: Greg | C29: Wirt | E29: 27 | G29: discuten | M29: Greg | N29: Wirt | O29: discuten
B30: Beatríz | E30: 28 | G30: aparece | M30: Beatríz | N30: aparece
B31: Beatriz | E31: 29 | G31: guía | M31: Beatriz | N31: guía
B32: Greg | C32: Wirt | E32: 30 | G32: Huyen | M32: Greg | N32: Wirt | O32: Huyen
B33: Wirt | E33: 31 | F33: 0.0037268519 | G33: explora | M33: Wirt | N33: explora
B34: Greg | E34: 31 | F34: 0.0037268519 | G34: explora | M34: Greg | N34: explora
B35: Beatríz | E35: 32 | F35: 0.0056944444 | G35: guía | M35: Beatríz | N35: guía
B36: Greg | C36: Wirt | E36: 34 | G36: Encuentran | M36: Greg | N36: Wirt | O36: Encuentran | P36: un | Q36: mounstruo
B37: Wirt | E37: 35 | G37: disculpa | M37: Wirt | N37: se | O37: disculpa
B38: Greg | C38: Wirt | E38: 36 | G38: Huyen | M38: Greg | N38: Wirt | O38: Huyen
B39: Greg | C39: Wirt | E39: 37 | G39: Encuentran | M39: Greg | N39: Wirt | O39: Encuentran | P39: un | Q39: mounstruo
B40: Greg | C40: Beatríz | E40: 38 | G40: Huyen | M40: Greg | N40: Beatríz | O40: Huyen
B41: Wirt | E41: 39 | G41: disculpa | M41: Wirt | N41: de | O41: disculpa
...

Sheet Asignar letras
A2: Adeline aparece | B2: E1
A3: Adeline muere | B3: E2
A4: Anciano aparece | B4: E3
A5: Anciano Mujer discuten | B5: E4
A6: Anciano se preocupa | B6: E5
A7: Animales cantan | B7: E6
A8: Beatríz Adeline discuten | B8: E7
A9: Beatríz aparece | B9: E8
A10: Beatríz busca a Wirt y Greg | B10: E9
A11: Beatríz grita | B11: E10
A12: Beatríz guía | B12: E11
A13: Beatríz huye | B13: E12
... A101: Wirt vaga | B101: E100
