Workbook

Sheet Datos
A1: Qué ocurre | B1: Código
A2: Greg y Wirt Vagan | B2: =VLOOKUP(A2, 'Asignar letras'!$A$2:$B$100, 2, 0) -> E57
A3: Wirt se preocupa | B3: =VLOOKUP(A3, 'Asignar letras'!$A$2:$B$100, 2, 0) -> E96
A4: Greg Wirt discuten | B4: =VLOOKUP(A4, 'Asignar letras'!$A$2:$B$100, 2, 0) -> E47
A5: Beatríz aparece | B5: =VLOOKUP(A5, 'Asignar letras'!$A$2:$B$100, 2, 0) -> E7
A6: Greg Wirt discuten | B6: =VLOOKUP(A6, 'Asignar letras'!$A$2:$B$100, 2, 0) -> E47
A7: Leñador aparece | B7: =VLOOKUP(A7, 'Asignar letras'!$A$2:$B$100, 2, 0) -> E62
A8: Leñador advierte | B8: =VLOOKUP(A8, 'Asignar letras'!$A$2:$B$100, 2, 0) -> E61
A9: Leñador guía | B9: =VLOOKUP(A9, 'Asignar letras'!$A$2:$B$100, 2, 0) -> E64
A10: Leñador advierte | B10: =VLOOKUP(A10, 'Asignar letras'!$A$2:$B$100, 2, 0) -> E61
A11: Wirt se preocupa | B11: =VLOOKUP(A11, 'Asignar letras'!$A$2:$B$100, 2, 0) -> E96
A12: Greg Wirt discuten | B12: =VLOOKUP(A12, 'Asignar letras'!$A$2:$B$100, 2, 0) -> E47
A13: Leñador advierte | B13: =VLOOKUP(A13, 'Asignar letras'!$A$2:$B$100, 2, 0) -> E61
... A231: Tiempo avanza | B231: =VLOOKUP(A231, 'Asignar letras'!$A$2:$B$100, 2, 0) -> E80

Sheet Hoja1
A1: Serie: | B1: Más allá del Jardín
B3: Qué ocurre | D3: Timestamp | G3: A entonces B, Tal Ventana (Tamaño de la ventana) | L3: Dudas: | M3: El libro dice que support es: "De todos los casos… ¿en cuántos aparecen X y Y juntos?"
A4: Episodio 1 | B4: Greg y Wirt Vagan | C4: =VLOOKUP(B4, 'Asignar letras'!$A$2:$B$100, 2, 0) -> E57 | D4: 6.9444444e-05 | M4: Con "todos los casos" se refiere a todas las ventanas que se forman de 2 + Ventanas de 3 + Ventanas de 4… etc--
B5: Wirt se preocupa | C5: =VLOOKUP(B5, 'Asignar letras'!$A$2:$B$100, 2, 0) -> E96 | D5: 0.00021990741 | G5: Leer reglas de asociación.
B6: Greg Wirt discuten | C6: =VLOOKUP(B6, 'Asignar letras'!$A$2:$B$100, 2, 0) -> E47 | D6: 0.0030324074 | G6: No hacer reglas compuestas. | M6: No entendí la diferencia entre: | P6: Support | Q6: Pag 120
B7: Beatríz aparece | C7: =VLOOKUP(B7, 'Asignar letras'!$A$2:$B$100, 2, 0) -> E7 | D7: 0.008125 | G7: Leer y traer preguntas. | P7: Confianza | Q7: Pag 120
B8: Greg Wirt discuten | C8: =VLOOKUP(B8, 'Asignar letras'!$A$2:$B$100, 2, 0) -> E47 | D8: 0.0089583333 | G8: Variable de consecuente.
B9: Leñador aparece | C9: =VLOOKUP(B9, 'Asignar letras'!$A$2:$B$100, 2, 0) -> E62 | D9: 0.050625 | M9: Entiendo que el "lift" es una medida de qué tan relacionados están
B10: Leñador advierte | C10: =VLOOKUP(B10, 'Asignar letras'!$A$2:$B$100, 2, 0) -> E61 | D10: 0.092291667 | N10: 1 = No hay relación | Q10: ¿Tengo que calcular eso también?
B11: Leñador guía | C11: =VLOOKUP(B11, 'Asignar letras'!$A$2:$B$100, 2, 0) -> E64 | D11: 0.13395833 | N11: >1 = Hay relación
B12: Leñador advierte | C12: =VLOOKUP(B12, 'Asignar letras'!$A$2:$B$100, 2, 0) -> E61 | D12: 0.175625 | N12: <1 = Relación negativa
B13: Wirt se preocupa | C13: =VLOOKUP(B13, 'Asignar letras'!$A$2:$B$100, 2, 0) -> E96 | D13: 0.21729167
B14: Greg Wirt discuten | C14: =VLOOKUP(B14, 'Asignar letras'!$A$2:$B$100, 2, 0) -> E47 | D14: 0.25895833
B15: Leñador advierte | C15: =VLOOKUP(B15, 'Asignar letras'!$A$2:$B$100, 2, 0) -> E61 | D15: 0.300625
B16: Greg Juega | C16: =VLOOKUP(B16, 'Asignar letras'!$A$2:$B$100, 2, 0) -> E34 | D16: 0.34229167
B17: Wirt se preocupa | C17: =VLOOKUP(B17, 'Asignar letras'!$A$2:$B$100, 2, 0) -> E96 | D17: 0.38395833
B18: Greg Explora | C18: =VLOOKUP(B18, 'Asignar letras'!$A$2:$B$100, 2, 0) -> E33 | D18: 0.425625
B19: Greg Wirt Encuentran un mounstruo | C19: =VLOOKUP(B19, 'Asignar letras'!$A$2:$B$100, 2, 0) -> E48 | D19: 0.46729167
B20: Greg Wirt Huyen | C20: =VLOOKUP(B20, 'Asignar letras'!$A$2:$B$100, 2, 0) -> E50 | D20: 0.50895833
B21: Leñador Pelea | C21: =VLOOKUP(B21, 'Asignar letras'!$A$2:$B$100, 2, 0) -> E66 | D21: 0.550625
B22: Greg Wirt Huyen | C22: =VLOOKUP(B22, 'Asignar letras'!$A$2:$B$100, 2, 0) -> E50 | D22: 0.59229167
B23: Leñador aparece | C23: =VLOOKUP(B23, 'Asignar letras'!$A$2:$B$100, 2, 0) -> E62 | D23: 0.63395833
B24: Leñador advierte | C24: =VLOOKUP(B24, 'Asignar letras'!$A$2:$B$100, 2, 0) -> E61 | D24: 0.675625 | G24: Tenemos que terminar con una tabla así: | J24: Pendiente leer lo de la cocina
B25: Greg Wirt discuten | C25: =VLOOKUP(B25, 'Asignar letras'!$A$2:$B$100, 2, 0) -> E47 | D25: 0.71729167 | G25: Regla | H25: Tamaño ventana
B26: Leñador advierte | C26: =VLOOKUP(B26, 'Asignar letras'!$A$2:$B$100, 2, 0) -> E61 | D26: 0.75895833 | G26: A Entonces B | H26: 3
B27: Wirt se disculpa | C27: =VLOOKUP(B27, 'Asignar letras'!$A$2:$B$100, 2, 0) -> E95 | D27: 0.800625 | G27: A Entonces B | H27: N-1
B28: Greg Wirt Huyen | C28: =VLOOKUP(B28, 'Asignar letras'!$A$2:$B$100, 2, 0) -> E50 | D28: 0.84229167
A29: Episodio 2 | B29: Greg Juega | C29: =VLOOKUP(B29, 'Asignar letras'!$A$2:$B$100, 2, 0) -> E34 | D29: 0.88395833
B30: Greg Wirt discuten | C30: =VLOOKUP(B30, 'Asignar letras'!$A$2:$B$100, 2, 0) -> E47 | D30: 0.925625
B31: Beatríz aparece | C31: =VLOOKUP(B31, 'Asignar letras'!$A$2:$B$100, 2, 0) -> E7 | D31: 0.96729167
B32: Beatríz guía | C32: =VLOOKUP(B32, 'Asignar letras'!$A$2:$B$100, 2, 0) -> E10 | D32: 1.0089583
B33: Greg Wirt Huyen | C33: =VLOOKUP(B33, 'Asignar letras'!$A$2:$B$100, 2, 0) -> E50 | D33: 1.050625
B34: Wirt explora | C34: =VLOOKUP(B34, 'Asignar letras'!$A$2:$B$100, 2, 0) -> E90 | D34: 0.0037268519
B35: Greg explora | C35: =VLOOKUP(B35, 'Asignar letras'!$A$2:$B$100, 2, 0) -> E33 | D35: 0.0037268519
B36: Beatríz guía | C36: =VLOOKUP(B36, 'Asignar letras'!$A$2:$B$100, 2, 0) -> E10 | D36: 0.0056944444
B37: Bestia aparece | C37: =VLOOKUP(B37, 'Asignar letras'!$A$2:$B$100, 2, 0) -> E17
B38: Wirt se prepara | C38: =VLOOKUP(B38, 'Asignar letras'!$A$2:$B$100, 2, 0) -> E97 | D38: 0.96729167
B39: Wirt se disculpa | C39: =VLOOKUP(B39, 'Asignar letras'!$A$2:$B$100, 2, 0) -> E95 | D39: 1.0089583
B40: Greg Wirt Huyen | C40: =VLOOKUP(B40, 'Asignar letras'!$A$2:$B$100, 2, 0) -> E50 | D40: 1.050625
B41: Bestia aparece | C41: =VLOOKUP(B41, 'Asignar letras'!$A$2:$B$100, 2, 0) -> E17 | D41: 0.0037268519
...

Sheet Separar predicados
B2: Persona | E2: Seq Num | F2: Cuándo | G2: Qué hizo
A3: Episodio 1 | B3: Greg | C3: Wirt | E3: 1 | F3: 6.9444444e-05 | G3: Vagan | M3: Greg | N3: Wirt | O3: Vagan
B4: Wirt | E4: 2 | F4: 0.00021990741 | G4: preocupa | M4: Wirt | N4: se | O4: preocupa
B5: Greg | C5: Wirt | E5: 3 | F5: 0.0030324074 | G5: discuten | M5: Greg | N5: Wirt | O5: discuten
B6: Beatríz | E6: 4 | F6: 0.008125 | G6: aparece | M6: Beatríz | N6: aparece
B7: Greg | C7: Wirt | E7: 5 | F7: 0.0089583333 | G7: discuten | M7: Greg | N7: Wirt | O7: discuten
B8: Leñador | E8: 6 | G8: aparece | M8: Leñador | N8: aparece
B9: Leñador | E9: 7 | G9: advierte | M9: Leñador | N9: advierte
B10: Leñador | E10: 8 | G10: guía | M10: Leñador | N10: guía
B11: Leñador | E11: 9 | G11: advierte | M11: Leñador | N11: advierte
B12: Wirt | E12: 10 | G12: preocupa | M12: Wirt | N12: se | O12: preocupa
B13: Greg | C13: Wirt | E13: 11 | G13: discuten | M13: Greg | N13: Wirt | O13: discuten
B14: Leñador | E14: 12 | G14: advierte | M14: Leñador | N14: advierte
B15: Greg | E15: 13 | G15: Juega | M15: Greg | N15: Juega
B16: Wirt | E16: 14 | G16: preocupa | M16: Wirt | N16: se | O16: preocupa
B17: Greg | E17: 15 | G17: Explora | M17: Greg | N17: Explora
B18: Greg | C18: Wirt | E18: 16 | G18: Encuentran | M18: Greg | N18: Wirt | O18: Encuentran | P18: un | Q18: mounstruo
B19: Greg | C19: Wirt | E19: 17 | G19: Huyen | M19: Greg | N19: Wirt | O19: Huyen
B20: Leñador | E20: 18 | G20: Pelea | M20: Leñador | N20: Pelea
B21: Greg | C21: Wirt | E21: 19 | G21: Huyen | M21: Greg | N21: Wirt | O21: Huyen
B22: Leñador | E22: 20 | G22: aparece | M22: Leñador | N22: aparece
B23: Leñador | E23: 21 | G23: advierte | M23: Leñador | N23: advierte
B24: Greg | C24: Wirt | E24: 22 | G24: discuten | M24: Greg | N24: Wirt | O24: discuten
B25: Leñador | E25: 23 | G25: advierte | M25: Leñador | N25: advierte
B26: Wirt | E26: 24 | G26: disculpa | M26: Wirt | N26: se | O26: disculpa
B27: Greg | C27: Wirt | E27: 25 | G27: Huyen | M27: Greg | N27: Wirt | O27: Huyen
A28: Episodio 2 | B28: Greg | E28: 26 | G28: Juega | M28: Greg | N28: Juega
B29: Greg | C29: Wirt | E29: 27 | G29: discuten | M29: Greg | N29: Wirt | O29: discuten
B30: Beatríz | E30: 28 | G30: aparece | M30: Beatríz | N30: aparece
B31: Beatriz | E31: 29 | G31: guía | M31: Beatriz | N31: guía
B32: Greg | C32: Wirt | E32: 30 | G32: Huyen | M32: Greg | N32: Wirt | O32: Huyen
B33: Wirt | E33: 31 | F33: 0.0037268519 | G33: explora | M33: Wirt | N33: explora
B34: Greg | E34: 31 | F34: 0.0037268519 | G34: explora | M34: Greg | N34: explora
B35: Beatríz | E35: 32 | F35: 0.0056944444 | G35: guía | M35: Beatríz | N35: guía
B36: Greg | C36: Wirt | E36: 34 | G36: Encuentran | M36: Greg | N36: Wirt | O36: Encuentran | P36: un | Q36: mounstruo
B37: Wirt | E37: 35 | G37: disculpa | M37: Wirt | N37: se | O37: disculpa
B38: Greg | C38: Wirt | E38: 36 | G38: Huyen | M38: Greg | N38: Wirt | O38: Huyen
B39: Greg | C39: Wirt | E39: 37 | G39: Encuentran | M39: Greg | N39: Wirt | O39: Encuentran | P39: un | Q39: mounstruo
B40: Greg | C40: Beatríz | E40: 38 | G40: Huyen | M40: Greg | N40: Beatríz | O40: Huyen
B41: Wirt | E41: 39 | G41: disculpa | M41: Wirt | N41: de | O41: disculpa
...

Sheet Asignar letras
A2: Adeline aparece | B2: E1
A3: Adeline muere | B3: E2
A4: Anciano aparece | B4: E3
A5: Anciano Mujer discuten | B5: E4
A6: Animales cantan | B6: E5
A7: Beatríz Adeline discuten | B7: E6
A8: Beatríz aparece | B8: E7
A9: Beatríz busca a Wirt y Greg | B9: E8
A10: Beatríz grita | B10: E9
A11: Beatríz guía | B11: E10
A12: Beatríz huye | B12: E11
A13: Beatríz lucha | B13: E12
... A100: Wirt vaga | B100: E99
