Workbook

Sheet eve práctico
A1: Make | B1: Electric Vehicle Type | C1: Clean Alternative Fuel Vehicle (CAFV) Eligibility
A2: TESLA | B2: Battery Electric Vehicle (BEV) | C2: Clean Alternative Fuel Vehicle Eligible | H2: MTE
A3: NISSAN | B3: Battery Electric Vehicle (BEV) | C3: Clean Alternative Fuel Vehicle Eligible | H3: MET
A4: JEEP | B4: Plug-in Hybrid Electric Vehicle (PHEV) | C4: Not eligible due to low battery range | H4: ETM
A5: AUDI | B5: Plug-in Hybrid Electric Vehicle (PHEV) | C5: Not eligible due to low battery range | H5: EMT
A6: NISSAN | B6: Battery Electric Vehicle (BEV) | C6: Clean Alternative Fuel Vehicle Eligible | H6: TEM
A7: VOLVO | B7: Plug-in Hybrid Electric Vehicle (PHEV) | C7: Clean Alternative Fuel Vehicle Eligible | H7: TME
A8: CHEVROLET | B8: Plug-in Hybrid Electric Vehicle (PHEV) | C8: Clean Alternative Fuel Vehicle Eligible
A9: TESLA | B9: Battery Electric Vehicle (BEV) | C9: Clean Alternative Fuel Vehicle Eligible | H9: MTE
A10: VOLVO | B10: Plug-in Hybrid Electric Vehicle (PHEV) | C10: Not eligible due to low battery range | O10: MET
A11: TESLA | B11: Battery Electric Vehicle (BEV) | C11: Clean Alternative Fuel Vehicle Eligible | H11: M: | I11: Frecuencia ABS | J11: Frecuencia Rel | K11: Entropía | M11: Entropía de este árbol: | O11: M: | P11: Frecuencia ABS | Q11: Frecuencia Rel | R11: Entropía | T11: Entropía de este árbol
A12: TESLA | B12: Battery Electric Vehicle (BEV) | C12: Clean Alternative Fuel Vehicle Eligible | E12: AUDI | H12: =_xlfn.CONCAT($H$11,'Datos auxiliares'!A2) -> M:AUDI | I12: =COUNTIF(Tabla2[Make],SUBSTITUTE(H12,$H$11,"")) -> 4 | J12: =I12 / $I$27 -> 0.04 | K12: =-LOG10(J12) * J12 -> 0.0559176 | M12: =K27 -> 0.93273558 | O12: =_xlfn.CONCAT($O$11, E12) -> M:AUDI | P12: =COUNTIF(Tabla2[Make],SUBSTITUTE(O12,$O$11,"")) -> 4 | Q12: =P12 / $P$27 -> 0.04 | R12: =-LOG10(Q12) * J12 -> 0.0559176 | T12: =R27 -> 0.93273558
A13: JEEP | B13: Plug-in Hybrid Electric Vehicle (PHEV) | C13: Not eligible due to low battery range | E13: BMW | H13: =_xlfn.CONCAT($H$11,'Datos auxiliares'!A3) -> M:BMW | I13: =COUNTIF(Tabla2[Make],SUBSTITUTE(H13,$H$11,"")) -> 16 | J13: =I13 / $I$27 -> 0.16 | K13: =-LOG10(J13) * J13 -> 0.1273408 | O13: =_xlfn.CONCAT($O$11, E13) -> M:BMW | P13: =COUNTIF(Tabla2[Make],SUBSTITUTE(O13,$O$11,"")) -> 16 | Q13: =P13 / $P$27 -> 0.16 | R13: =-LOG10(Q13) * J13 -> 0.1273408
A14: FIAT | B14: Battery Electric Vehicle (BEV) | C14: Clean Alternative Fuel Vehicle Eligible | E14: CADILLAC | H14: =_xlfn.CONCAT($H$11,'Datos auxiliares'!A4) -> M:CADILLAC | I14: =COUNTIF(Tabla2[Make],SUBSTITUTE(H14,$H$11,"")) -> 1 | J14: =I14 / $I$27 -> 0.01 | K14: =-LOG10(J14) * J14 -> 0.02 | O14: =_xlfn.CONCAT($O$11, E14) -> M:CADILLAC | P14: =COUNTIF(Tabla2[Make],SUBSTITUTE(O14,$O$11,"")) -> 1 | Q14: =P14 / $P$27 -> 0.01 | R14: =-LOG10(Q14) * J14 -> 0.02
A15: TESLA | B15: Battery Electric Vehicle (BEV) | C15: Clean Alternative Fuel Vehicle Eligible | E15: CHEVROLET | H15: =_xlfn.CONCAT($H$11,'Datos auxiliares'!A5) -> M:CHEVROLET | I15: =COUNTIF(Tabla2[Make],SUBSTITUTE(H15,$H$11,"")) -> 5 | J15: =I15 / $I$27 -> 0.05 | K15: =-LOG10(J15) * J15 -> 0.0650515 | O15: =_xlfn.CONCAT($O$11, E15) -> M:CHEVROLET | P15: =COUNTIF(Tabla2[Make],SUBSTITUTE(O15,$O$11,"")) -> 5 | Q15: =P15 / $P$27 -> 0.05 | R15: =-LOG10(Q15) * J15 -> 0.0650515
A16: TESLA | B16: Battery Electric Vehicle (BEV) | C16: Clean Alternative Fuel Vehicle Eligible | E16: FIAT | H16: =_xlfn.CONCAT($H$11,'Datos auxiliares'!A6) -> M:FIAT | I16: =COUNTIF(Tabla2[Make],SUBSTITUTE(H16,$H$11,"")) -> 2 | J16: =I16 / $I$27 -> 0.02 | K16: =-LOG10(J16) * J16 -> 0.0339794 | O16: =_xlfn.CONCAT($O$11, E16) -> M:FIAT | P16: =COUNTIF(Tabla2[Make],SUBSTITUTE(O16,$O$11,"")) -> 2 | Q16: =P16 / $P$27 -> 0.02 | R16: =-LOG10(Q16) * J16 -> 0.0339794
A17: KIA | B17: Battery Electric Vehicle (BEV) | C17: Clean Alternative Fuel Vehicle Eligible | E17: FORD | H17: =_xlfn.CONCAT($H$11,'Datos auxiliares'!A7) -> M:FORD | I17: =COUNTIF(Tabla2[Make],SUBSTITUTE(H17,$H$11,"")) -> 2 | J17: =I17 / $I$27 -> 0.02 | K17: =-LOG10(J17) * J17 -> 0.0339794 | O17: =_xlfn.CONCAT($O$11, E17) -> M:FORD | P17: =COUNTIF(Tabla2[Make],SUBSTITUTE(O17,$O$11,"")) -> 2 | Q17: =P17 / $P$27 -> 0.02 | R17: =-LOG10(Q17) * J17 -> 0.0339794
A18: NISSAN | B18: Battery Electric Vehicle (BEV) | C18: Clean Alternative Fuel Vehicle Eligible | E18: HYUNDAI | H18: =_xlfn.CONCAT($H$11,'Datos auxiliares'!A8) -> M:HYUNDAI | I18: =COUNTIF(Tabla2[Make],SUBSTITUTE(H18,$H$11,"")) -> 1 | J18: =I18 / $I$27 -> 0.01 | K18: =-LOG10(J18) * J18 -> 0.02 | O18: =_xlfn.CONCAT($O$11, E18) -> M:HYUNDAI | P18: =COUNTIF(Tabla2[Make],SUBSTITUTE(O18,$O$11,"")) -> 1 | Q18: =P18 / $P$27 -> 0.01 | R18: =-LOG10(Q18) * J18 -> 0.02
A19: BMW | B19: Plug-in Hybrid Electric Vehicle (PHEV) | C19: Not eligible due to low battery range | E19: JEEP | H19: =_xlfn.CONCAT($H$11,'Datos auxiliares'!A9) -> M:JEEP | I19: =COUNTIF(Tabla2[Make],SUBSTITUTE(H19,$H$11,"")) -> 4 | J19: =I19 / $I$27 -> 0.04 | K19: =-LOG10(J19) * J19 -> 0.0559176 | O19: =_xlfn.CONCAT($O$11, E19) -> M:JEEP | P19: =COUNTIF(Tabla2[Make],SUBSTITUTE(O19,$O$11,"")) -> 4 | Q19: =P19 / $P$27 -> 0.04 | R19: =-LOG10(Q19) * J19 -> 0.0559176
A20: VOLVO | B20: Plug-in Hybrid Electric Vehicle (PHEV) | C20: Clean Alternative Fuel Vehicle Eligible | E20: KIA | H20: =_xlfn.CONCAT($H$11,'Datos auxiliares'!A10) -> M:KIA | I20: =COUNTIF(Tabla2[Make],SUBSTITUTE(H20,$H$11,"")) -> 13 | J20: =I20 / $I$27 -> 0.13 | K20: =-LOG10(J20) * J20 -> 0.11518736 | O20: =_xlfn.CONCAT($O$11, E20) -> M:KIA | P20: =COUNTIF(Tabla2[Make],SUBSTITUTE(O20,$O$11,"")) -> 13 | Q20: =P20 / $P$27 -> 0.13 | R20: =-LOG10(Q20) * J20 -> 0.11518736
A21: BMW | B21: Plug-in Hybrid Electric Vehicle (PHEV) | C21: Clean Alternative Fuel Vehicle Eligible | E21: NISSAN | H21: =_xlfn.CONCAT($H$11,'Datos auxiliares'!A11) -> M:NISSAN | I21: =COUNTIF(Tabla2[Make],SUBSTITUTE(H21,$H$11,"")) -> 13 | J21: =I21 / $I$27 -> 0.13 | K21: =-LOG10(J21) * J21 -> 0.11518736 | O21: =_xlfn.CONCAT($O$11, E21) -> M:NISSAN | P21: =COUNTIF(Tabla2[Make],SUBSTITUTE(O21,$O$11,"")) -> 13 | Q21: =P21 / $P$27 -> 0.13 | R21: =-LOG10(Q21) * J21 -> 0.11518736
A22: TESLA | B22: Battery Electric Vehicle (BEV) | C22: Clean Alternative Fuel Vehicle Eligible | E22: POLESTAR | H22: =_xlfn.CONCAT($H$11,'Datos auxiliares'!A12) -> M:POLESTAR | I22: =COUNTIF(Tabla2[Make],SUBSTITUTE(H22,$H$11,"")) -> 1 | J22: =I22 / $I$27 -> 0.01 | K22: =-LOG10(J22) * J22 -> 0.02 | O22: =_xlfn.CONCAT($O$11, E22) -> M:POLESTAR | P22: =COUNTIF(Tabla2[Make],SUBSTITUTE(O22,$O$11,"")) -> 1 | Q22: =P22 / $P$27 -> 0.01 | R22: =-LOG10(Q22) * J22 -> 0.02
A23: NISSAN | B23: Battery Electric Vehicle (BEV) | C23: Clean Alternative Fuel Vehicle Eligible | E23: PORSCHE | H23: =_xlfn.CONCAT($H$11,'Datos auxiliares'!A13) -> M:PORSCHE | I23: =COUNTIF(Tabla2[Make],SUBSTITUTE(H23,$H$11,"")) -> 1 | J23: =I23 / $I$27 -> 0.01 | K23: =-LOG10(J23) * J23 -> 0.02 | O23: =_xlfn.CONCAT($O$11, E23) -> M:PORSCHE | P23: =COUNTIF(Tabla2[Make],SUBSTITUTE(O23,$O$11,"")) -> 1 | Q23: =P23 / $P$27 -> 0.01 | R23: =-LOG10(Q23) * J23 -> 0.02
A24: BMW | B24: Plug-in Hybrid Electric Vehicle (PHEV) | C24: Clean Alternative Fuel Vehicle Eligible | E24: TESLA | H24: =_xlfn.CONCAT($H$11,'Datos auxiliares'!A14) -> M:TESLA | I24: =COUNTIF(Tabla2[Make],SUBSTITUTE(H24,$H$11,"")) -> 30 | J24: =I24 / $I$27 -> 0.3 | K24: =-LOG10(J24) * J24 -> 0.15686362 | O24: =_xlfn.CONCAT($O$11, E24) -> M:TESLA | P24: =COUNTIF(Tabla2[Make],SUBSTITUTE(O24,$O$11,"")) -> 30 | Q24: =P24 / $P$27 -> 0.3 | R24: =-LOG10(Q24) * J24 -> 0.15686362
... A26: KIA | B26: Battery Electric Vehicle (BEV) | C26: Clean Alternative Fuel Vehicle Eligible | E26: VOLVO | H26: =_xlfn.CONCAT($H$11,'Datos auxiliares'!A16) -> M:VOLVO | I26: =COUNTIF(Tabla2[Make],SUBSTITUTE(H26,$H$11,"")) -> 6 | J26: =I26 / $I$27 -> 0.06 | K26: =-LOG10(J26) * J26 -> 0.073310925 | O26: =_xlfn.CONCAT($O$11, E26) -> M:VOLVO | P26: =COUNTIF(Tabla2[Make],SUBSTITUTE(O26,$O$11,"")) -> 6 | Q26: =P26 / $P$27 -> 0.06 | R26: =-LOG10(Q26) * J26 -> 0.073310925
A27: KIA | B27: Plug-in Hybrid Electric Vehicle (PHEV) | C27: Not eligible due to low battery range | I27: =SUM(I12:I26) -> 100 | J27: =SUM(J12:J26) -> 1 | K27: =SUM(K12:K26) -> 0.93273558 | P27: =SUM(P12:P26) -> 100 | Q27: 1 | R27: 0.93273558
A28: TESLA | B28: Battery Electric Vehicle (BEV) | C28: Eligibility unknown as battery range has not been researched
A29: KIA | B29: Battery Electric Vehicle (BEV) | C29: Clean Alternative Fuel Vehicle Eligible | H29: MT: | I29: Frecuencia ABS | J29: Frecuencia Rel | K29: Entropia | M29: Entropía de este árbol: | O29: ME:
A30: TESLA | B30: Battery Electric Vehicle (BEV) | C30: Eligibility unknown as battery range has not been researched | E30: AUDI | F30: B | H30: =_xlfn.CONCAT(_xlfn.CONCAT($H$29,'Datos auxiliares'!A2),"-B") -> MT:AUDI-B | I30: =COUNTIFS( Tabla2[Make], E30, Tabla2[Electric Vehicle Type], _xlfn.IFS(F30 = "B",'Datos auxiliares'!$B$2,F30 = "P",'Datos auxiliares'!$B$3)) -> 1 | J30: =I30 / $I$60 -> 0.01 | K30: =IFERROR(-LOG10(J30) * J30, "No hay Log de 0") -> 0.02 | M30: =K60 -> 0.0850515 | O30: =_xlfn.CONCAT($O$29, E12, "-", G63) -> ME:AUDI-C | P30: =COUNTIF( Tabla2[Make], SUBSTITUTE( SUBSTITUTE( SUBSTITUTE( SUBSTITUTE( SUBSTITUTE( SUBSTITUTE( SUBSTITUTE( SUBSTITUTE( SUBSTITUTE( SUBSTITUTE( SUBSTITUTE( SUBSTITUTE( SUBSTITUTE( SUBSTITUTE( SUBSTITUTE( SUBSTITUTE( SUBSTITUTE( SUBSTITUTE( SUBSTITUTE(O30,$O$29,""),"AUDI",""),"BMW",""),"CADILLAC",""),"CHEVROLET",""),"FIAT",""),"FORD",""),"HYUNDAI",""),"JEEP",""),"KIA",""),"NISSAN",""),"POLESTAR",""),"PORSCHE",""),"TESLA",""),"VOLKSWAGEN",""),"VOLVO",""),"-C",'Datos auxiliares'!$C$4),"-E",'Datos auxiliares'!$C$3),"-N",'Datos auxiliares'!$C$3) ) -> 0 | Q30: =SUBSTITUTE( SUBSTITUTE(O30, $O$29, ""),'Datos auxiliares'!A2:A16+'Datos auxiliares'!A2:A16,"") -> #VALUE!
A31: KIA | B31: Battery Electric Vehicle (BEV) | C31: Clean Alternative Fuel Vehicle Eligible | E31: AUDI | F31: P | H31: =_xlfn.CONCAT(_xlfn.CONCAT($H$29,'Datos auxiliares'!A2),"-P") -> MT:AUDI-P | I31: =COUNTIFS( Tabla2[Make], E31, Tabla2[Electric Vehicle Type], _xlfn.IFS(F31 = "B",'Datos auxiliares'!$B$2,F31 = "P",'Datos auxiliares'!$B$3)) -> 3 | J31: =I31 / $I$60 -> 0.03 | K31: =IFERROR(-LOG10(J31) * J31, "No hay Log de 0") -> 0.045686362 | O31: =_xlfn.CONCAT($O$29, E12, "-", G64) -> ME:AUDI-E | P31: =COUNTIF( Tabla2[Make], SUBSTITUTE( SUBSTITUTE( SUBSTITUTE( SUBSTITUTE( SUBSTITUTE( SUBSTITUTE( SUBSTITUTE( SUBSTITUTE( SUBSTITUTE( SUBSTITUTE( SUBSTITUTE( SUBSTITUTE( SUBSTITUTE( SUBSTITUTE( SUBSTITUTE( SUBSTITUTE( SUBSTITUTE( SUBSTITUTE( SUBSTITUTE(O31,$O$29,""),"AUDI",""),"BMW",""),"CADILLAC",""),"CHEVROLET",""),"FIAT",""),"FORD",""),"HYUNDAI",""),"JEEP",""),"KIA",""),"NISSAN",""),"POLESTAR",""),"PORSCHE",""),"TESLA",""),"VOLKSWAGEN",""),"VOLVO",""),"-C",'Datos auxiliares'!$C$4),"-E",'Datos auxiliares'!$C$3),"-N",'Datos auxiliares'!$C$3) ) -> 0
A32: NISSAN | B32: Battery Electric Vehicle (BEV) | C32: Clean Alternative Fuel Vehicle Eligible | E32: BMW | F32: B | H32: =_xlfn.CONCAT(_xlfn.CONCAT($H$29,'Datos auxiliares'!A3),"-B") -> MT:BMW-B | I32: =COUNTIFS( Tabla2[Make], E32, Tabla2[Electric Vehicle Type], _xlfn.IFS(F32 = "B",'Datos auxiliares'!$B$2,F32 = "P",'Datos auxiliares'!$B$3)) -> 3 | J32: =I32 / $I$60 -> 0.03 | K32: =IFERROR(-LOG10(J32) * J32, "No hay Log de 0") -> 0.045686362 | O32: =_xlfn.CONCAT($O$29, E12, "-", G65) -> ME:AUDI-N | P32: =COUNTIF( Tabla2[Make], SUBSTITUTE( SUBSTITUTE( SUBSTITUTE( SUBSTITUTE( SUBSTITUTE( SUBSTITUTE( SUBSTITUTE( SUBSTITUTE( SUBSTITUTE( SUBSTITUTE( SUBSTITUTE( SUBSTITUTE( SUBSTITUTE( SUBSTITUTE( SUBSTITUTE( SUBSTITUTE( SUBSTITUTE( SUBSTITUTE( SUBSTITUTE(O32,$O$29,""),"AUDI",""),"BMW",""),"CADILLAC",""),"CHEVROLET",""),"FIAT",""),"FORD",""),"HYUNDAI",""),"JEEP",""),"KIA",""),"NISSAN",""),"POLESTAR",""),"PORSCHE",""),"TESLA",""),"VOLKSWAGEN",""),"VOLVO",""),"-C",'Datos auxiliares'!$C$4),"-E",'Datos auxiliares'!$C$3),"-N",'Datos auxiliares'!$C$3) ) -> 0
A33: TESLA | B33: Battery Electric Vehicle (BEV) | C33: Clean Alternative Fuel Vehicle Eligible | E33: BMW | F33: P | H33: =_xlfn.CONCAT(_xlfn.CONCAT($H$29,'Datos auxiliares'!A3),"-P") -> MT:BMW-P | I33: =COUNTIFS( Tabla2[Make], E33, Tabla2[Electric Vehicle Type], _xlfn.IFS(F33 = "B",'Datos auxiliares'!$B$2,F33 = "P",'Datos auxiliares'!$B$3)) -> 13 | J33: =I33 / $I$60 -> 0.13 | K33: =IFERROR(-LOG10(J33) * J33, "No hay Log de 0") -> 0.11518736 | O33: =_xlfn.CONCAT($O$29, E13, "-", G66) -> ME:BMW-C | P33: =COUNTIF( Tabla2[Make], SUBSTITUTE( SUBSTITUTE( SUBSTITUTE( SUBSTITUTE( SUBSTITUTE( SUBSTITUTE( SUBSTITUTE( SUBSTITUTE( SUBSTITUTE( SUBSTITUTE( SUBSTITUTE( SUBSTITUTE( SUBSTITUTE( SUBSTITUTE( SUBSTITUTE( SUBSTITUTE( SUBSTITUTE( SUBSTITUTE( SUBSTITUTE(O33,$O$29,""),"AUDI",""),"BMW",""),"CADILLAC",""),"CHEVROLET",""),"FIAT",""),"FORD",""),"HYUNDAI",""),"JEEP",""),"KIA",""),"NISSAN",""),"POLESTAR",""),"PORSCHE",""),"TESLA",""),"VOLKSWAGEN",""),"VOLVO",""),"-C",'Datos auxiliares'!$C$4),"-E",'Datos auxiliares'!$C$3),"-N",'Datos auxiliares'!$C$3) ) -> 0
A34: TESLA | B34: Battery Electric Vehicle (BEV) | C34: Clean Alternative Fuel Vehicle Eligible | E34: CADILLAC | F34: B | H34: =_xlfn.CONCAT(_xlfn.CONCAT($H$29,'Datos auxiliares'!A4),"-B") -> MT:CADILLAC-B | I34: =COUNTIFS( Tabla2[Make], E34, Tabla2[Electric Vehicle Type], _xlfn.IFS(F34 = "B",'Datos auxiliares'!$B$2,F34 = "P",'Datos auxiliares'!$B$3)) -> 0 | J34: =I34 / $I$60 -> 0 | K34: =IFERROR(-LOG10(J34) * J34, "No hay Log de 0") -> No hay Log de 0 | O34: =_xlfn.CONCAT($O$29, E13, "-", G67) -> ME:BMW-E | P34: =COUNTIF( Tabla2[Make], SUBSTITUTE( SUBSTITUTE( SUBSTITUTE( SUBSTITUTE( SUBSTITUTE( SUBSTITUTE( SUBSTITUTE( SUBSTITUTE( SUBSTITUTE( SUBSTITUTE( SUBSTITUTE( SUBSTITUTE( SUBSTITUTE( SUBSTITUTE( SUBSTITUTE( SUBSTITUTE( SUBSTITUTE( SUBSTITUTE( SUBSTITUTE(O34,$O$29,""),"AUDI",""),"BMW",""),"CADILLAC",""),"CHEVROLET",""),"FIAT",""),"FORD",""),"HYUNDAI",""),"JEEP",""),"KIA",""),"NISSAN",""),"POLESTAR",""),"PORSCHE",""),"TESLA",""),"VOLKSWAGEN",""),"VOLVO",""),"-C",'Datos auxiliares'!$C$4),"-E",'Datos auxiliares'!$C$3),"-N",'Datos auxiliares'!$C$3) ) -> 0
A35: TESLA | B35: Battery Electric Vehicle (BEV) | C35: Clean Alternative Fuel Vehicle Eligible | E35: CADILLAC | F35: P | H35: =_xlfn.CONCAT(_xlfn.CONCAT($H$29,'Datos auxiliares'!A4),"-P") -> MT:CADILLAC-P | I35: =COUNTIFS( Tabla2[Make], E35, Tabla2[Electric Vehicle Type], _xlfn.IFS(F35 = "B",'Datos auxiliares'!$B$2,F35 = "P",'Datos auxiliares'!$B$3)) -> 1 | J35: =I35 / $I$60 -> 0.01 | K35: =IFERROR(-LOG10(J35) * J35, "No hay Log de 0") -> 0.02 | O35: =_xlfn.CONCAT($O$29, E13, "-", G68) -> ME:BMW-N | P35: =COUNTIF( Tabla2[Make], SUBSTITUTE( SUBSTITUTE( SUBSTITUTE( SUBSTITUTE( SUBSTITUTE( SUBSTITUTE( SUBSTITUTE( SUBSTITUTE( SUBSTITUTE( SUBSTITUTE( SUBSTITUTE( SUBSTITUTE( SUBSTITUTE( SUBSTITUTE( SUBSTITUTE( SUBSTITUTE( SUBSTITUTE( SUBSTITUTE( SUBSTITUTE(O35,$O$29,""),"AUDI",""),"BMW",""),"CADILLAC",""),"CHEVROLET",""),"FIAT",""),"FORD",""),"HYUNDAI",""),"JEEP",""),"KIA",""),"NISSAN",""),"POLESTAR",""),"PORSCHE",""),"TESLA",""),"VOLKSWAGEN",""),"VOLVO",""),"-C",'Datos auxiliares'!$C$4),"-E",'Datos auxiliares'!$C$3),"-N",'Datos auxiliares'!$C$3) ) -> 0
A36: HYUNDAI | B36: Plug-in Hybrid Electric Vehicle (PHEV) | C36: Clean Alternative Fuel Vehicle Eligible | E36: CHEVROLET | F36: B | H36: =_xlfn.CONCAT(_xlfn.CONCAT($H$29,'Datos auxiliares'!A5),"-B") -> MT:CHEVROLET-B | I36: =COUNTIFS( Tabla2[Make], E36, Tabla2[Electric Vehicle Type], _xlfn.IFS(F36 = "B",'Datos auxiliares'!$B$2,F36 = "P",'Datos auxiliares'!$B$3)) -> 3 | J36: =I36 / $I$60 -> 0.03 | K36: =IFERROR(-LOG10(J36) * J36, "No hay Log de 0") -> 0.045686362 | O36: =_xlfn.CONCAT($O$29, E18, "-", G69) -> ME:HYUNDAI-C | P36: =COUNTIF( Tabla2[Make], SUBSTITUTE( SUBSTITUTE( SUBSTITUTE( SUBSTITUTE( SUBSTITUTE( SUBSTITUTE( SUBSTITUTE( SUBSTITUTE( SUBSTITUTE( SUBSTITUTE( SUBSTITUTE( SUBSTITUTE( SUBSTITUTE( SUBSTITUTE( SUBSTITUTE( SUBSTITUTE( SUBSTITUTE( SUBSTITUTE( SUBSTITUTE(O36,$O$29,""),"AUDI",""),"BMW",""),"CADILLAC",""),"CHEVROLET",""),"FIAT",""),"FORD",""),"HYUNDAI",""),"JEEP",""),"KIA",""),"NISSAN",""),"POLESTAR",""),"PORSCHE",""),"TESLA",""),"VOLKSWAGEN",""),"VOLVO",""),"-C",'Datos auxiliares'!$C$4),"-E",'Datos auxiliares'!$C$3),"-N",'Datos auxiliares'!$C$3) ) -> 0
A37: BMW | B37: Plug-in Hybrid Electric Vehicle (PHEV) | C37: Not eligible due to low battery range | E37: CHEVROLET | F37: P | H37: =_xlfn.CONCAT(_xlfn.CONCAT($H$29,'Datos auxiliares'!A5),"-P") -> MT:CHEVROLET-P | I37: =COUNTIFS( Tabla2[Make], E37, Tabla2[Electric Vehicle Type], _xlfn.IFS(F37 = "B",'Datos auxiliares'!$B$2,F37 = "P",'Datos auxiliares'!$B$3)) -> 2 | J37: =I37 / $I$60 -> 0.02 | K37: =IFERROR(-LOG10(J37) * J37, "No hay Log de 0") -> 0.0339794 | O37: =_xlfn.CONCAT($O$29, E18, "-", G70) -> ME:HYUNDAI-E | P37: =COUNTIF( Tabla2[Make], SUBSTITUTE( SUBSTITUTE( SUBSTITUTE( SUBSTITUTE( SUBSTITUTE( SUBSTITUTE( SUBSTITUTE( SUBSTITUTE( SUBSTITUTE( SUBSTITUTE( SUBSTITUTE( SUBSTITUTE( SUBSTITUTE( SUBSTITUTE( SUBSTITUTE( SUBSTITUTE( SUBSTITUTE( SUBSTITUTE( SUBSTITUTE(O37,$O$29,""),"AUDI",""),"BMW",""),"CADILLAC",""),"CHEVROLET",""),"FIAT",""),"FORD",""),"HYUNDAI",""),"JEEP",""),"KIA",""),"NISSAN",""),"POLESTAR",""),"PORSCHE",""),"TESLA",""),"VOLKSWAGEN",""),"VOLVO",""),"-C",'Datos auxiliares'!$C$4),"-E",'Datos auxiliares'!$C$3),"-N",'Datos auxiliares'!$C$3) ) -> 0
A38: BMW | B38: Plug-in Hybrid Electric Vehicle (PHEV) | C38: Clean Alternative Fuel Vehicle Eligible | E38: FIAT | F38: B | H38: =_xlfn.CONCAT(_xlfn.CONCAT($H$29,'Datos auxiliares'!A6),"-B") -> MT:FIAT-B | I38: =COUNTIFS( Tabla2[Make], E38, Tabla2[Electric Vehicle Type], _xlfn.IFS(F38 = "B",'Datos auxiliares'!$B$2,F38 = "P",'Datos auxiliares'!$B$3)) -> 2 | J38: =I38 / $I$60 -> 0.02 | K38: =IFERROR(-LOG10(J38) * J38, "No hay Log de 0") -> 0.0339794 | O38: =_xlfn.CONCAT($O$29, E18, "-", G71) -> ME:HYUNDAI-N | P38: =COUNTIF( Tabla2[Make], SUBSTITUTE( SUBSTITUTE( SUBSTITUTE( SUBSTITUTE( SUBSTITUTE( SUBSTITUTE( SUBSTITUTE( SUBSTITUTE( SUBSTITUTE( SUBSTITUTE( SUBSTITUTE( SUBSTITUTE( SUBSTITUTE( SUBSTITUTE( SUBSTITUTE( SUBSTITUTE( SUBSTITUTE( SUBSTITUTE( SUBSTITUTE(O38,$O$29,""),"AUDI",""),"BMW",""),"CADILLAC",""),"CHEVROLET",""),"FIAT",""),"FORD",""),"HYUNDAI",""),"JEEP",""),"KIA",""),"NISSAN",""),"POLESTAR",""),"PORSCHE",""),"TESLA",""),"VOLKSWAGEN",""),"VOLVO",""),"-C",'Datos auxiliares'!$C$4),"-E",'Datos auxiliares'!$C$3),"-N",'Datos auxiliares'!$C$3) ) -> 0
A39: BMW | B39: Plug-in Hybrid Electric Vehicle (PHEV) | C39: Clean Alternative Fuel Vehicle Eligible | E39: FIAT | F39: P | H39: =_xlfn.CONCAT(_xlfn.CONCAT($H$29,'Datos auxiliares'!A6),"-P") -> MT:FIAT-P | I39: =COUNTIFS( Tabla2[Make], E39, Tabla2[Electric Vehicle Type], _xlfn.IFS(F39 = "B",'Datos auxiliares'!$B$2,F39 = "P",'Datos auxiliares'!$B$3)) -> 0 | J39: =I39 / $I$60 -> 0 | K39: =IFERROR(-LOG10(J39) * J39, "No hay Log de 0") -> No hay Log de 0 | O39: =_xlfn.CONCAT($O$29, E19, "-", G72) -> ME:JEEP-C | P39: =COUNTIF( Tabla2[Make], SUBSTITUTE( SUBSTITUTE( SUBSTITUTE( SUBSTITUTE( SUBSTITUTE( SUBSTITUTE( SUBSTITUTE( SUBSTITUTE( SUBSTITUTE( SUBSTITUTE( SUBSTITUTE( SUBSTITUTE( SUBSTITUTE( SUBSTITUTE( SUBSTITUTE( SUBSTITUTE( SUBSTITUTE( SUBSTITUTE( SUBSTITUTE(O39,$O$29,""),"AUDI",""),"BMW",""),"CADILLAC",""),"CHEVROLET",""),"FIAT",""),"FORD",""),"HYUNDAI",""),"JEEP",""),"KIA",""),"NISSAN",""),"POLESTAR",""),"PORSCHE",""),"TESLA",""),"VOLKSWAGEN",""),"VOLVO",""),"-C",'Datos auxiliares'!$C$4),"-E",'Datos auxiliares'!$C$3),"-N",'Datos auxiliares'!$C$3) ) -> 0
A40: NISSAN | B40: Battery Electric Vehicle (BEV) | C40: Clean Alternative Fuel Vehicle Eligible | E40: FORD | F40: B | H40: =_xlfn.CONCAT(_xlfn.CONCAT($H$29,'Datos auxiliares'!A7),"-B") -> MT:FORD-B | I40: =COUNTIFS( Tabla2[Make], E40, Tabla2[Electric Vehicle Type], _xlfn.IFS(F40 = "B",'Datos auxiliares'!$B$2,F40 = "P",'Datos auxiliares'!$B$3)) -> 1 | J40: =I40 / $I$60 -> 0.01 | K40: =IFERROR(-LOG10(J40) * J40, "No hay Log de 0") -> 0.02 | O40: =_xlfn.CONCAT($O$29, E19, "-", G73) -> ME:JEEP-E | P40: =COUNTIF( Tabla2[Make], SUBSTITUTE( SUBSTITUTE( SUBSTITUTE( SUBSTITUTE( SUBSTITUTE( SUBSTITUTE( SUBSTITUTE( SUBSTITUTE( SUBSTITUTE( SUBSTITUTE( SUBSTITUTE( SUBSTITUTE( SUBSTITUTE( SUBSTITUTE( SUBSTITUTE( SUBSTITUTE( SUBSTITUTE( SUBSTITUTE( SUBSTITUTE(O40,$O$29,""),"AUDI",""),"BMW",""),"CADILLAC",""),"CHEVROLET",""),"FIAT",""),"FORD",""),"HYUNDAI",""),"JEEP",""),"KIA",""),"NISSAN",""),"POLESTAR",""),"PORSCHE",""),"TESLA",""),"VOLKSWAGEN",""),"VOLVO",""),"-C",'Datos auxiliares'!$C$4),"-E",'Datos auxiliares'!$C$3),"-N",'Datos auxiliares'!$C$3) ) -> 0
A41: KIA | B41: Plug-in Hybrid Electric Vehicle (PHEV) | C41: Clean Alternative Fuel Vehicle Eligible | E41: FORD | F41: P | H41: =_xlfn.CONCAT(_xlfn.CONCAT($H$29,'Datos auxiliares'!A7),"-P") -> MT:FORD-P | I41: =COUNTIFS( Tabla2[Make], E41, Tabla2[Electric Vehicle Type], _xlfn.IFS(F41 = "B",'Datos auxiliares'!$B$2,F41 = "P",'Datos auxiliares'!$B$3)) -> 1 | J41: =I41 / $I$60 -> 0.01 | K41: =IFERROR(-LOG10(J41) * J41, "No hay Log de 0") -> 0.02 | O41: =_xlfn.CONCAT($O$29, E19, "-", G74) -> ME:JEEP-N | P41: =COUNTIF( Tabla2[Make], SUBSTITUTE( SUBSTITUTE( SUBSTITUTE( SUBSTITUTE( SUBSTITUTE( SUBSTITUTE( SUBSTITUTE( SUBSTITUTE( SUBSTITUTE( SUBSTITUTE( SUBSTITUTE( SUBSTITUTE( SUBSTITUTE( SUBSTITUTE( SUBSTITUTE( SUBSTITUTE( SUBSTITUTE( SUBSTITUTE( SUBSTITUTE(O41,$O$29,""),"AUDI",""),"BMW",""),"CADILLAC",""),"CHEVROLET",""),"FIAT",""),"FORD",""),"HYUNDAI",""),"JEEP",""),"KIA",""),"NISSAN",""),"POLESTAR",""),"PORSCHE",""),"TESLA",""),"VOLKSWAGEN",""),"VOLVO",""),"-C",'Datos auxiliares'!$C$4),"-E",'Datos auxiliares'!$C$3),"-N",'Datos auxiliares'!$C$3) ) -> 0
...

Sheet Datos auxiliares
A1: Modelos de coche | B1: Tipo de vehículo | C1: Elegibilidad | D1: Quitar letras
A2: AUDI | B2: Battery Electric Vehicle (BEV) | C2: Not eligible due to low battery range | D2: =SUBSTITUTE(SUBSTITUTE(SUBSTITUTE(SUBSTITUTE(SUBSTITUTE(SUBSTITUTE(SUBSTITUTE(SUBSTITUTE(SUBSTITUTE(SUBSTITUTE(SUBSTITUTE(SUBSTITUTE(SUBSTITUTE(SUBSTITUTE(SUBSTITUTE(A2,"AUDI", ""), "BMW", ""),"CADILLAC", ""), "CHEVROLET", ""), "FIAT", ""), "FORD", ""), "HYUNDAI", ""), "JEEP", ""), "KIA", ""), "NISSAN", ""), "POLESTAR", ""), "PORSCHE", ""),"TESLA", ""), "VOLKSWAGEN", ""),"VOLVO", "")
A3: BMW | B3: Plug-in Hybrid Electric Vehicle (PHEV) | C3: Eligibility unknown as battery range has not been researched | D3: =SUBSTITUTE(SUBSTITUTE(SUBSTITUTE(SUBSTITUTE(SUBSTITUTE(SUBSTITUTE(SUBSTITUTE(SUBSTITUTE(SUBSTITUTE(SUBSTITUTE(SUBSTITUTE(SUBSTITUTE(SUBSTITUTE(SUBSTITUTE(SUBSTITUTE(A3,"AUDI", ""), "BMW", ""),"CADILLAC", ""), "CHEVROLET", ""), "FIAT", ""), "FORD", ""), "HYUNDAI", ""), "JEEP", ""), "KIA", ""), "NISSAN", ""), "POLESTAR", ""), "PORSCHE", ""),"TESLA", ""), "VOLKSWAGEN", ""),"VOLVO", "")
A4: CADILLAC | C4: Clean Alternative Fuel Vehicle Eligible | D4: =SUBSTITUTE(SUBSTITUTE(SUBSTITUTE(SUBSTITUTE(SUBSTITUTE(SUBSTITUTE(SUBSTITUTE(SUBSTITUTE(SUBSTITUTE(SUBSTITUTE(SUBSTITUTE(SUBSTITUTE(SUBSTITUTE(SUBSTITUTE(SUBSTITUTE(A4,"AUDI", ""), "BMW", ""),"CADILLAC", ""), "CHEVROLET", ""), "FIAT", ""), "FORD", ""), "HYUNDAI", ""), "JEEP", ""), "KIA", ""), "NISSAN", ""), "POLESTAR", ""), "PORSCHE", ""),"TESLA", ""), "VOLKSWAGEN", ""),"VOLVO", "")
A5: CHEVROLET | D5: =SUBSTITUTE(SUBSTITUTE(SUBSTITUTE(SUBSTITUTE(SUBSTITUTE(SUBSTITUTE(SUBSTITUTE(SUBSTITUTE(SUBSTITUTE(SUBSTITUTE(SUBSTITUTE(SUBSTITUTE(SUBSTITUTE(SUBSTITUTE(SUBSTITUTE(A5,"AUDI", ""), "BMW", ""),"CADILLAC", ""), "CHEVROLET", ""), "FIAT", ""), "FORD", ""), "HYUNDAI", ""), "JEEP", ""), "KIA", ""), "NISSAN", ""), "POLESTAR", ""), "PORSCHE", ""),"TESLA", ""), "VOLKSWAGEN", ""),"VOLVO", "")
A6: FIAT | D6: =SUBSTITUTE(SUBSTITUTE(SUBSTITUTE(SUBSTITUTE(SUBSTITUTE(SUBSTITUTE(SUBSTITUTE(SUBSTITUTE(SUBSTITUTE(SUBSTITUTE(SUBSTITUTE(SUBSTITUTE(SUBSTITUTE(SUBSTITUTE(SUBSTITUTE(A6,"AUDI", ""), "BMW", ""),"CADILLAC", ""), "CHEVROLET", ""), "FIAT", ""), "FORD", ""), "HYUNDAI", ""), "JEEP", ""), "KIA", ""), "NISSAN", ""), "POLESTAR", ""), "PORSCHE", ""),"TESLA", ""), "VOLKSWAGEN", ""),"VOLVO", "")
A7: FORD | D7: =SUBSTITUTE(SUBSTITUTE(SUBSTITUTE(SUBSTITUTE(SUBSTITUTE(SUBSTITUTE(SUBSTITUTE(SUBSTITUTE(SUBSTITUTE(SUBSTITUTE(SUBSTITUTE(SUBSTITUTE(SUBSTITUTE(SUBSTITUTE(SUBSTITUTE(A7,"AUDI", ""), "BMW", ""),"CADILLAC", ""), "CHEVROLET", ""), "FIAT", ""), "FORD", ""), "HYUNDAI", ""), "JEEP", ""), "KIA", ""), "NISSAN", ""), "POLESTAR", ""), "PORSCHE", ""),"TESLA", ""), "VOLKSWAGEN", ""),"VOLVO", "")
A8: HYUNDAI | D8: =SUBSTITUTE(SUBSTITUTE(SUBSTITUTE(SUBSTITUTE(SUBSTITUTE(SUBSTITUTE(SUBSTITUTE(SUBSTITUTE(SUBSTITUTE(SUBSTITUTE(SUBSTITUTE(SUBSTITUTE(SUBSTITUTE(SUBSTITUTE(SUBSTITUTE(A8,"AUDI", ""), "BMW", ""),"CADILLAC", ""), "CHEVROLET", ""), "FIAT", ""), "FORD", ""), "HYUNDAI", ""), "JEEP", ""), "KIA", ""), "NISSAN", ""), "POLESTAR", ""), "PORSCHE", ""),"TESLA", ""), "VOLKSWAGEN", ""),"VOLVO", "")
A9: JEEP | D9: =SUBSTITUTE(SUBSTITUTE(SUBSTITUTE(SUBSTITUTE(SUBSTITUTE(SUBSTITUTE(SUBSTITUTE(SUBSTITUTE(SUBSTITUTE(SUBSTITUTE(SUBSTITUTE(SUBSTITUTE(SUBSTITUTE(SUBSTITUTE(SUBSTITUTE(A9,"AUDI", ""), "BMW", ""),"CADILLAC", ""), "CHEVROLET", ""), "FIAT", ""), "FORD", ""), "HYUNDAI", ""), "JEEP", ""), "KIA", ""), "NISSAN", ""), "POLESTAR", ""), "PORSCHE", ""),"TESLA", ""), "VOLKSWAGEN", ""),"VOLVO", "")
A10: KIA | D10: =SUBSTITUTE(SUBSTITUTE(SUBSTITUTE(SUBSTITUTE(SUBSTITUTE(SUBSTITUTE(SUBSTITUTE(SUBSTITUTE(SUBSTITUTE(SUBSTITUTE(SUBSTITUTE(SUBSTITUTE(SUBSTITUTE(SUBSTITUTE(SUBSTITUTE(A10,"AUDI", ""), "BMW", ""),"CADILLAC", ""), "CHEVROLET", ""), "FIAT", ""), "FORD", ""), "HYUNDAI", ""), "JEEP", ""), "KIA", ""), "NISSAN", ""), "POLESTAR", ""), "PORSCHE", ""),"TESLA", ""), "VOLKSWAGEN", ""),"VOLVO", "")
A11: NISSAN | D11: =SUBSTITUTE(SUBSTITUTE(SUBSTITUTE(SUBSTITUTE(SUBSTITUTE(SUBSTITUTE(SUBSTITUTE(SUBSTITUTE(SUBSTITUTE(SUBSTITUTE(SUBSTITUTE(SUBSTITUTE(SUBSTITUTE(SUBSTITUTE(SUBSTITUTE(A11,"AUDI", ""), "BMW", ""),"CADILLAC", ""), "CHEVROLET", ""), "FIAT", ""), "FORD", ""), "HYUNDAI", ""), "JEEP", ""), "KIA", ""), "NISSAN", ""), "POLESTAR", ""), "PORSCHE", ""),"TESLA", ""), "VOLKSWAGEN", ""),"VOLVO", "")
A12: POLESTAR | D12: =SUBSTITUTE(SUBSTITUTE(SUBSTITUTE(SUBSTITUTE(SUBSTITUTE(SUBSTITUTE(SUBSTITUTE(SUBSTITUTE(SUBSTITUTE(SUBSTITUTE(SUBSTITUTE(SUBSTITUTE(SUBSTITUTE(SUBSTITUTE(SUBSTITUTE(A12,"AUDI", ""), "BMW", ""),"CADILLAC", ""), "CHEVROLET", ""), "FIAT", ""), "FORD", ""), "HYUNDAI", ""), "JEEP", ""), "KIA", ""), "NISSAN", ""), "POLESTAR", ""), "PORSCHE", ""),"TESLA", ""), "VOLKSWAGEN", ""),"VOLVO", "")
A13: PORSCHE | D13: =SUBSTITUTE(SUBSTITUTE(SUBSTITUTE(SUBSTITUTE(SUBSTITUTE(SUBSTITUTE(SUBSTITUTE(SUBSTITUTE(SUBSTITUTE(SUBSTITUTE(SUBSTITUTE(SUBSTITUTE(SUBSTITUTE(SUBSTITUTE(SUBSTITUTE(A13,"AUDI", ""), "BMW", ""),"CADILLAC", ""), "CHEVROLET", ""), "FIAT", ""), "FORD", ""), "HYUNDAI", ""), "JEEP", ""), "KIA", ""), "NISSAN", ""), "POLESTAR", ""), "PORSCHE", ""),"TESLA", ""), "VOLKSWAGEN", ""),"VOLVO", "")
A14: TESLA | D14: =SUBSTITUTE(SUBSTITUTE(SUBSTITUTE(SUBSTITUTE(SUBSTITUTE(SUBSTITUTE(SUBSTITUTE(SUBSTITUTE(SUBSTITUTE(SUBSTITUTE(SUBSTITUTE(SUBSTITUTE(SUBSTITUTE(SUBSTITUTE(SUBSTITUTE(A14,"AUDI", ""), "BMW", ""),"CADILLAC", ""), "CHEVROLET", ""), "FIAT", ""), "FORD", ""), "HYUNDAI", ""), "JEEP", ""), "KIA", ""), "NISSAN", ""), "POLESTAR", ""), "PORSCHE", ""),"TESLA", ""), "VOLKSWAGEN", ""),"VOLVO", "")
A15: VOLKSWAGEN | D15: =SUBSTITUTE(SUBSTITUTE(SUBSTITUTE(SUBSTITUTE(SUBSTITUTE(SUBSTITUTE(SUBSTITUTE(SUBSTITUTE(SUBSTITUTE(SUBSTITUTE(SUBSTITUTE(SUBSTITUTE(SUBSTITUTE(SUBSTITUTE(SUBSTITUTE(A15,"AUDI", ""), "BMW", ""),"CADILLAC", ""), "CHEVROLET", ""), "FIAT", ""), "FORD", ""), "HYUNDAI", ""), "JEEP", ""), "KIA", ""), "NISSAN", ""), "POLESTAR", ""), "PORSCHE", ""),"TESLA", ""), "VOLKSWAGEN", ""),"VOLVO", "")
A16: VOLVO | D16: =SUBSTITUTE(SUBSTITUTE(SUBSTITUTE(SUBSTITUTE(SUBSTITUTE(SUBSTITUTE(SUBSTITUTE(SUBSTITUTE(SUBSTITUTE(SUBSTITUTE(SUBSTITUTE(SUBSTITUTE(SUBSTITUTE(SUBSTITUTE(SUBSTITUTE(A16,"AUDI", ""), "BMW", ""),"CADILLAC", ""), "CHEVROLET", ""), "FIAT", ""), "FORD", ""), "HYUNDAI", ""), "JEEP", ""), "KIA", ""), "NISSAN", ""), "POLESTAR", ""), "PORSCHE", ""),"TESLA", ""), "VOLKSWAGEN", ""),"VOLVO", "")
